[2022-10-13T22:08:53.904+0000] {taskinstance.py:1165} INFO - Dependencies all met for <TaskInstance: DesafioAirflow.task3 scheduled__2022-10-12T00:00:00+00:00 [queued]>
[2022-10-13T22:08:53.933+0000] {taskinstance.py:1165} INFO - Dependencies all met for <TaskInstance: DesafioAirflow.task3 scheduled__2022-10-12T00:00:00+00:00 [queued]>
[2022-10-13T22:08:53.934+0000] {taskinstance.py:1362} INFO - 
--------------------------------------------------------------------------------
[2022-10-13T22:08:53.935+0000] {taskinstance.py:1363} INFO - Starting attempt 2 of 2
[2022-10-13T22:08:53.935+0000] {taskinstance.py:1364} INFO - 
--------------------------------------------------------------------------------
[2022-10-13T22:08:53.996+0000] {taskinstance.py:1383} INFO - Executing <Task(PythonOperator): task3> on 2022-10-12 00:00:00+00:00
[2022-10-13T22:08:54.014+0000] {standard_task_runner.py:54} INFO - Started process 259 to run task
[2022-10-13T22:08:54.021+0000] {standard_task_runner.py:82} INFO - Running: ['***', 'tasks', 'run', 'DesafioAirflow', 'task3', 'scheduled__2022-10-12T00:00:00+00:00', '--job-id', '44', '--raw', '--subdir', 'DAGS_FOLDER/desafioAirflow/desafio-indicium.py', '--cfg-path', '/tmp/tmpd0a58eq3']
[2022-10-13T22:08:54.022+0000] {standard_task_runner.py:83} INFO - Job 44: Subtask task3
[2022-10-13T22:08:54.023+0000] {dagbag.py:525} INFO - Filling up the DagBag from /opt/***/dags/desafioAirflow/desafio-indicium.py
[2022-10-13T22:08:54.731+0000] {task_command.py:384} INFO - Running <TaskInstance: DesafioAirflow.task3 scheduled__2022-10-12T00:00:00+00:00 [running]> on host 8943fa1d9abf
[2022-10-13T22:08:54.885+0000] {taskinstance.py:1592} INFO - Exporting the following env vars:
AIRFLOW_CTX_DAG_OWNER=***
AIRFLOW_CTX_DAG_ID=DesafioAirflow
AIRFLOW_CTX_TASK_ID=task3
AIRFLOW_CTX_EXECUTION_DATE=2022-10-12T00:00:00+00:00
AIRFLOW_CTX_TRY_NUMBER=2
AIRFLOW_CTX_DAG_RUN_ID=scheduled__2022-10-12T00:00:00+00:00
[2022-10-13T22:08:54.903+0000] {taskinstance.py:1851} ERROR - Task failed with exception
Traceback (most recent call last):
  File "/home/airflow/.local/lib/python3.7/site-packages/airflow/operators/python.py", line 175, in execute
    return_value = self.execute_callable()
  File "/home/airflow/.local/lib/python3.7/site-packages/airflow/operators/python.py", line 193, in execute_callable
    return self.python_callable(*self.op_args, **self.op_kwargs)
  File "/opt/airflow/dags/desafioAirflow/desafio-indicium.py", line 23, in export_final_answer
    my_email = Variable.get("my_email")
  File "/home/airflow/.local/lib/python3.7/site-packages/airflow/models/variable.py", line 141, in get
    raise KeyError(f'Variable {key} does not exist')
KeyError: 'Variable my_email does not exist'
[2022-10-13T22:08:54.919+0000] {taskinstance.py:1406} INFO - Marking task as FAILED. dag_id=DesafioAirflow, task_id=task3, execution_date=20221012T000000, start_date=20221013T220853, end_date=20221013T220854
[2022-10-13T22:08:54.945+0000] {standard_task_runner.py:107} ERROR - Failed to execute job 44 for task task3 ('Variable my_email does not exist'; 259)
[2022-10-13T22:08:54.996+0000] {local_task_job.py:164} INFO - Task exited with return code 1
[2022-10-13T22:08:55.039+0000] {local_task_job.py:273} INFO - 0 downstream tasks scheduled from follow-on schedule check
