[2022-10-13T22:08:59.024+0000] {taskinstance.py:1165} INFO - Dependencies all met for <TaskInstance: DesafioAirflow.task3 manual__2022-10-13T22:07:50.211216+00:00 [queued]>
[2022-10-13T22:08:59.054+0000] {taskinstance.py:1165} INFO - Dependencies all met for <TaskInstance: DesafioAirflow.task3 manual__2022-10-13T22:07:50.211216+00:00 [queued]>
[2022-10-13T22:08:59.055+0000] {taskinstance.py:1362} INFO - 
--------------------------------------------------------------------------------
[2022-10-13T22:08:59.056+0000] {taskinstance.py:1363} INFO - Starting attempt 2 of 2
[2022-10-13T22:08:59.056+0000] {taskinstance.py:1364} INFO - 
--------------------------------------------------------------------------------
[2022-10-13T22:08:59.095+0000] {taskinstance.py:1383} INFO - Executing <Task(PythonOperator): task3> on 2022-10-13 22:07:50.211216+00:00
[2022-10-13T22:08:59.109+0000] {standard_task_runner.py:54} INFO - Started process 271 to run task
[2022-10-13T22:08:59.115+0000] {standard_task_runner.py:82} INFO - Running: ['***', 'tasks', 'run', 'DesafioAirflow', 'task3', 'manual__2022-10-13T22:07:50.211216+00:00', '--job-id', '45', '--raw', '--subdir', 'DAGS_FOLDER/desafioAirflow/desafio-indicium.py', '--cfg-path', '/tmp/tmpxlfmi0r8']
[2022-10-13T22:08:59.115+0000] {standard_task_runner.py:83} INFO - Job 45: Subtask task3
[2022-10-13T22:08:59.117+0000] {dagbag.py:525} INFO - Filling up the DagBag from /opt/***/dags/desafioAirflow/desafio-indicium.py
[2022-10-13T22:08:59.817+0000] {task_command.py:384} INFO - Running <TaskInstance: DesafioAirflow.task3 manual__2022-10-13T22:07:50.211216+00:00 [running]> on host 8943fa1d9abf
[2022-10-13T22:08:59.970+0000] {taskinstance.py:1592} INFO - Exporting the following env vars:
AIRFLOW_CTX_DAG_OWNER=***
AIRFLOW_CTX_DAG_ID=DesafioAirflow
AIRFLOW_CTX_TASK_ID=task3
AIRFLOW_CTX_EXECUTION_DATE=2022-10-13T22:07:50.211216+00:00
AIRFLOW_CTX_TRY_NUMBER=2
AIRFLOW_CTX_DAG_RUN_ID=manual__2022-10-13T22:07:50.211216+00:00
[2022-10-13T22:08:59.990+0000] {taskinstance.py:1851} ERROR - Task failed with exception
Traceback (most recent call last):
  File "/home/airflow/.local/lib/python3.7/site-packages/airflow/operators/python.py", line 175, in execute
    return_value = self.execute_callable()
  File "/home/airflow/.local/lib/python3.7/site-packages/airflow/operators/python.py", line 193, in execute_callable
    return self.python_callable(*self.op_args, **self.op_kwargs)
  File "/opt/airflow/dags/desafioAirflow/desafio-indicium.py", line 23, in export_final_answer
    my_email = Variable.get("my_email")
  File "/home/airflow/.local/lib/python3.7/site-packages/airflow/models/variable.py", line 141, in get
    raise KeyError(f'Variable {key} does not exist')
KeyError: 'Variable my_email does not exist'
[2022-10-13T22:09:00.008+0000] {taskinstance.py:1406} INFO - Marking task as FAILED. dag_id=DesafioAirflow, task_id=task3, execution_date=20221013T220750, start_date=20221013T220859, end_date=20221013T220900
[2022-10-13T22:09:00.035+0000] {standard_task_runner.py:107} ERROR - Failed to execute job 45 for task task3 ('Variable my_email does not exist'; 271)
[2022-10-13T22:09:00.089+0000] {local_task_job.py:164} INFO - Task exited with return code 1
[2022-10-13T22:09:00.131+0000] {local_task_job.py:273} INFO - 0 downstream tasks scheduled from follow-on schedule check
