[2022-10-09T21:58:12.074+0000] {processor.py:156} INFO - Started process (PID=13583) to work on /opt/airflow/dags/desafio-airflow/desafio-indicium.py
[2022-10-09T21:58:12.075+0000] {processor.py:758} INFO - Processing file /opt/airflow/dags/desafio-airflow/desafio-indicium.py for tasks to queue
[2022-10-09T21:58:12.076+0000] {logging_mixin.py:117} INFO - [2022-10-09T21:58:12.076+0000] {dagbag.py:525} INFO - Filling up the DagBag from /opt/airflow/dags/desafio-airflow/desafio-indicium.py
[2022-10-09T21:58:12.453+0000] {logging_mixin.py:117} INFO - [2022-10-09T21:58:12.451+0000] {dagbag.py:330} ERROR - Failed to import: /opt/airflow/dags/desafio-airflow/desafio-indicium.py
Traceback (most recent call last):
  File "/home/airflow/.local/lib/python3.7/site-packages/airflow/models/dagbag.py", line 326, in parse
    loader.exec_module(new_module)
  File "<frozen importlib._bootstrap_external>", line 728, in exec_module
  File "<frozen importlib._bootstrap>", line 219, in _call_with_frames_removed
  File "/opt/airflow/dags/desafio-airflow/desafio-indicium.py", line 4, in <module>
    from scripts.func_le_dados import leitura
ModuleNotFoundError: No module named 'scripts'
[2022-10-09T21:58:12.453+0000] {processor.py:770} WARNING - No viable dags retrieved from /opt/airflow/dags/desafio-airflow/desafio-indicium.py
[2022-10-09T21:58:12.478+0000] {processor.py:178} INFO - Processing /opt/airflow/dags/desafio-airflow/desafio-indicium.py took 0.408 seconds
[2022-10-09T21:58:42.805+0000] {processor.py:156} INFO - Started process (PID=13648) to work on /opt/airflow/dags/desafio-airflow/desafio-indicium.py
[2022-10-09T21:58:42.812+0000] {processor.py:758} INFO - Processing file /opt/airflow/dags/desafio-airflow/desafio-indicium.py for tasks to queue
[2022-10-09T21:58:42.813+0000] {logging_mixin.py:117} INFO - [2022-10-09T21:58:42.813+0000] {dagbag.py:525} INFO - Filling up the DagBag from /opt/airflow/dags/desafio-airflow/desafio-indicium.py
[2022-10-09T21:58:43.140+0000] {logging_mixin.py:117} INFO - [2022-10-09T21:58:43.138+0000] {dagbag.py:330} ERROR - Failed to import: /opt/airflow/dags/desafio-airflow/desafio-indicium.py
Traceback (most recent call last):
  File "/home/airflow/.local/lib/python3.7/site-packages/airflow/models/dagbag.py", line 326, in parse
    loader.exec_module(new_module)
  File "<frozen importlib._bootstrap_external>", line 728, in exec_module
  File "<frozen importlib._bootstrap>", line 219, in _call_with_frames_removed
  File "/opt/airflow/dags/desafio-airflow/desafio-indicium.py", line 4, in <module>
    from scripts.func_le_dados import leitura
ModuleNotFoundError: No module named 'scripts'
[2022-10-09T21:58:43.140+0000] {processor.py:770} WARNING - No viable dags retrieved from /opt/airflow/dags/desafio-airflow/desafio-indicium.py
[2022-10-09T21:58:43.169+0000] {processor.py:178} INFO - Processing /opt/airflow/dags/desafio-airflow/desafio-indicium.py took 0.368 seconds
[2022-10-09T21:59:13.457+0000] {processor.py:156} INFO - Started process (PID=13705) to work on /opt/airflow/dags/desafio-airflow/desafio-indicium.py
[2022-10-09T21:59:13.458+0000] {processor.py:758} INFO - Processing file /opt/airflow/dags/desafio-airflow/desafio-indicium.py for tasks to queue
[2022-10-09T21:59:13.459+0000] {logging_mixin.py:117} INFO - [2022-10-09T21:59:13.459+0000] {dagbag.py:525} INFO - Filling up the DagBag from /opt/airflow/dags/desafio-airflow/desafio-indicium.py
[2022-10-09T21:59:13.725+0000] {logging_mixin.py:117} INFO - [2022-10-09T21:59:13.724+0000] {dagbag.py:330} ERROR - Failed to import: /opt/airflow/dags/desafio-airflow/desafio-indicium.py
Traceback (most recent call last):
  File "/home/airflow/.local/lib/python3.7/site-packages/airflow/models/dagbag.py", line 326, in parse
    loader.exec_module(new_module)
  File "<frozen importlib._bootstrap_external>", line 728, in exec_module
  File "<frozen importlib._bootstrap>", line 219, in _call_with_frames_removed
  File "/opt/airflow/dags/desafio-airflow/desafio-indicium.py", line 4, in <module>
    from scripts.func_le_dados import leitura
ModuleNotFoundError: No module named 'scripts'
[2022-10-09T21:59:13.725+0000] {processor.py:770} WARNING - No viable dags retrieved from /opt/airflow/dags/desafio-airflow/desafio-indicium.py
[2022-10-09T21:59:13.756+0000] {processor.py:178} INFO - Processing /opt/airflow/dags/desafio-airflow/desafio-indicium.py took 0.306 seconds
[2022-10-09T21:59:44.492+0000] {processor.py:156} INFO - Started process (PID=13771) to work on /opt/airflow/dags/desafio-airflow/desafio-indicium.py
[2022-10-09T21:59:44.493+0000] {processor.py:758} INFO - Processing file /opt/airflow/dags/desafio-airflow/desafio-indicium.py for tasks to queue
[2022-10-09T21:59:44.494+0000] {logging_mixin.py:117} INFO - [2022-10-09T21:59:44.493+0000] {dagbag.py:525} INFO - Filling up the DagBag from /opt/airflow/dags/desafio-airflow/desafio-indicium.py
[2022-10-09T21:59:44.789+0000] {logging_mixin.py:117} INFO - [2022-10-09T21:59:44.788+0000] {dagbag.py:330} ERROR - Failed to import: /opt/airflow/dags/desafio-airflow/desafio-indicium.py
Traceback (most recent call last):
  File "/home/airflow/.local/lib/python3.7/site-packages/airflow/models/dagbag.py", line 326, in parse
    loader.exec_module(new_module)
  File "<frozen importlib._bootstrap_external>", line 728, in exec_module
  File "<frozen importlib._bootstrap>", line 219, in _call_with_frames_removed
  File "/opt/airflow/dags/desafio-airflow/desafio-indicium.py", line 4, in <module>
    from scripts.func_le_dados import leitura
ModuleNotFoundError: No module named 'scripts'
[2022-10-09T21:59:44.790+0000] {processor.py:770} WARNING - No viable dags retrieved from /opt/airflow/dags/desafio-airflow/desafio-indicium.py
[2022-10-09T21:59:44.827+0000] {processor.py:178} INFO - Processing /opt/airflow/dags/desafio-airflow/desafio-indicium.py took 0.341 seconds
[2022-10-09T22:00:15.231+0000] {processor.py:156} INFO - Started process (PID=13827) to work on /opt/airflow/dags/desafio-airflow/desafio-indicium.py
[2022-10-09T22:00:15.239+0000] {processor.py:758} INFO - Processing file /opt/airflow/dags/desafio-airflow/desafio-indicium.py for tasks to queue
[2022-10-09T22:00:15.239+0000] {logging_mixin.py:117} INFO - [2022-10-09T22:00:15.239+0000] {dagbag.py:525} INFO - Filling up the DagBag from /opt/airflow/dags/desafio-airflow/desafio-indicium.py
[2022-10-09T22:00:15.581+0000] {logging_mixin.py:117} INFO - [2022-10-09T22:00:15.579+0000] {dagbag.py:330} ERROR - Failed to import: /opt/airflow/dags/desafio-airflow/desafio-indicium.py
Traceback (most recent call last):
  File "/home/airflow/.local/lib/python3.7/site-packages/airflow/models/dagbag.py", line 326, in parse
    loader.exec_module(new_module)
  File "<frozen importlib._bootstrap_external>", line 728, in exec_module
  File "<frozen importlib._bootstrap>", line 219, in _call_with_frames_removed
  File "/opt/airflow/dags/desafio-airflow/desafio-indicium.py", line 4, in <module>
    from scripts.func_le_dados import leitura
ModuleNotFoundError: No module named 'scripts'
[2022-10-09T22:00:15.581+0000] {processor.py:770} WARNING - No viable dags retrieved from /opt/airflow/dags/desafio-airflow/desafio-indicium.py
[2022-10-09T22:00:15.610+0000] {processor.py:178} INFO - Processing /opt/airflow/dags/desafio-airflow/desafio-indicium.py took 0.385 seconds
[2022-10-09T22:00:28.933+0000] {processor.py:156} INFO - Started process (PID=13869) to work on /opt/airflow/dags/desafio-airflow/desafio-indicium.py
[2022-10-09T22:00:28.940+0000] {processor.py:758} INFO - Processing file /opt/airflow/dags/desafio-airflow/desafio-indicium.py for tasks to queue
[2022-10-09T22:00:28.941+0000] {logging_mixin.py:117} INFO - [2022-10-09T22:00:28.941+0000] {dagbag.py:525} INFO - Filling up the DagBag from /opt/airflow/dags/desafio-airflow/desafio-indicium.py
[2022-10-09T22:00:29.263+0000] {logging_mixin.py:117} INFO - [2022-10-09T22:00:29.260+0000] {dagbag.py:330} ERROR - Failed to import: /opt/airflow/dags/desafio-airflow/desafio-indicium.py
Traceback (most recent call last):
  File "/home/airflow/.local/lib/python3.7/site-packages/airflow/models/dagbag.py", line 326, in parse
    loader.exec_module(new_module)
  File "<frozen importlib._bootstrap_external>", line 728, in exec_module
  File "<frozen importlib._bootstrap>", line 219, in _call_with_frames_removed
  File "/opt/airflow/dags/desafio-airflow/desafio-indicium.py", line 4, in <module>
    from scripts.func_le_dados import leitura
ModuleNotFoundError: No module named 'scripts'
[2022-10-09T22:00:29.264+0000] {processor.py:770} WARNING - No viable dags retrieved from /opt/airflow/dags/desafio-airflow/desafio-indicium.py
[2022-10-09T22:00:29.296+0000] {processor.py:178} INFO - Processing /opt/airflow/dags/desafio-airflow/desafio-indicium.py took 0.367 seconds
[2022-10-09T22:00:59.423+0000] {processor.py:156} INFO - Started process (PID=13924) to work on /opt/airflow/dags/desafio-airflow/desafio-indicium.py
[2022-10-09T22:00:59.430+0000] {processor.py:758} INFO - Processing file /opt/airflow/dags/desafio-airflow/desafio-indicium.py for tasks to queue
[2022-10-09T22:00:59.431+0000] {logging_mixin.py:117} INFO - [2022-10-09T22:00:59.431+0000] {dagbag.py:525} INFO - Filling up the DagBag from /opt/airflow/dags/desafio-airflow/desafio-indicium.py
[2022-10-09T22:00:59.737+0000] {logging_mixin.py:117} INFO - [2022-10-09T22:00:59.735+0000] {dagbag.py:330} ERROR - Failed to import: /opt/airflow/dags/desafio-airflow/desafio-indicium.py
Traceback (most recent call last):
  File "/home/airflow/.local/lib/python3.7/site-packages/airflow/models/dagbag.py", line 326, in parse
    loader.exec_module(new_module)
  File "<frozen importlib._bootstrap_external>", line 728, in exec_module
  File "<frozen importlib._bootstrap>", line 219, in _call_with_frames_removed
  File "/opt/airflow/dags/desafio-airflow/desafio-indicium.py", line 4, in <module>
    from scripts.func_le_dados import leitura
ModuleNotFoundError: No module named 'scripts'
[2022-10-09T22:00:59.738+0000] {processor.py:770} WARNING - No viable dags retrieved from /opt/airflow/dags/desafio-airflow/desafio-indicium.py
[2022-10-09T22:00:59.780+0000] {processor.py:178} INFO - Processing /opt/airflow/dags/desafio-airflow/desafio-indicium.py took 0.361 seconds
[2022-10-09T22:01:29.902+0000] {processor.py:156} INFO - Started process (PID=13990) to work on /opt/airflow/dags/desafio-airflow/desafio-indicium.py
[2022-10-09T22:01:29.903+0000] {processor.py:758} INFO - Processing file /opt/airflow/dags/desafio-airflow/desafio-indicium.py for tasks to queue
[2022-10-09T22:01:29.904+0000] {logging_mixin.py:117} INFO - [2022-10-09T22:01:29.904+0000] {dagbag.py:525} INFO - Filling up the DagBag from /opt/airflow/dags/desafio-airflow/desafio-indicium.py
[2022-10-09T22:01:30.316+0000] {logging_mixin.py:117} INFO - [2022-10-09T22:01:30.314+0000] {dagbag.py:330} ERROR - Failed to import: /opt/airflow/dags/desafio-airflow/desafio-indicium.py
Traceback (most recent call last):
  File "/home/airflow/.local/lib/python3.7/site-packages/airflow/models/dagbag.py", line 326, in parse
    loader.exec_module(new_module)
  File "<frozen importlib._bootstrap_external>", line 728, in exec_module
  File "<frozen importlib._bootstrap>", line 219, in _call_with_frames_removed
  File "/opt/airflow/dags/desafio-airflow/desafio-indicium.py", line 4, in <module>
    from scripts.func_le_dados import leitura
ModuleNotFoundError: No module named 'scripts'
[2022-10-09T22:01:30.317+0000] {processor.py:770} WARNING - No viable dags retrieved from /opt/airflow/dags/desafio-airflow/desafio-indicium.py
[2022-10-09T22:01:30.359+0000] {processor.py:178} INFO - Processing /opt/airflow/dags/desafio-airflow/desafio-indicium.py took 0.463 seconds
[2022-10-09T22:02:00.838+0000] {processor.py:156} INFO - Started process (PID=14047) to work on /opt/airflow/dags/desafio-airflow/desafio-indicium.py
[2022-10-09T22:02:00.840+0000] {processor.py:758} INFO - Processing file /opt/airflow/dags/desafio-airflow/desafio-indicium.py for tasks to queue
[2022-10-09T22:02:00.841+0000] {logging_mixin.py:117} INFO - [2022-10-09T22:02:00.840+0000] {dagbag.py:525} INFO - Filling up the DagBag from /opt/airflow/dags/desafio-airflow/desafio-indicium.py
[2022-10-09T22:02:01.095+0000] {logging_mixin.py:117} INFO - [2022-10-09T22:02:01.094+0000] {dagbag.py:330} ERROR - Failed to import: /opt/airflow/dags/desafio-airflow/desafio-indicium.py
Traceback (most recent call last):
  File "/home/airflow/.local/lib/python3.7/site-packages/airflow/models/dagbag.py", line 326, in parse
    loader.exec_module(new_module)
  File "<frozen importlib._bootstrap_external>", line 728, in exec_module
  File "<frozen importlib._bootstrap>", line 219, in _call_with_frames_removed
  File "/opt/airflow/dags/desafio-airflow/desafio-indicium.py", line 4, in <module>
    from scripts.func_le_dados import leitura
ModuleNotFoundError: No module named 'scripts'
[2022-10-09T22:02:01.095+0000] {processor.py:770} WARNING - No viable dags retrieved from /opt/airflow/dags/desafio-airflow/desafio-indicium.py
[2022-10-09T22:02:01.124+0000] {processor.py:178} INFO - Processing /opt/airflow/dags/desafio-airflow/desafio-indicium.py took 0.291 seconds
[2022-10-09T22:02:31.399+0000] {processor.py:156} INFO - Started process (PID=14110) to work on /opt/airflow/dags/desafio-airflow/desafio-indicium.py
[2022-10-09T22:02:31.400+0000] {processor.py:758} INFO - Processing file /opt/airflow/dags/desafio-airflow/desafio-indicium.py for tasks to queue
[2022-10-09T22:02:31.401+0000] {logging_mixin.py:117} INFO - [2022-10-09T22:02:31.401+0000] {dagbag.py:525} INFO - Filling up the DagBag from /opt/airflow/dags/desafio-airflow/desafio-indicium.py
[2022-10-09T22:02:31.751+0000] {logging_mixin.py:117} INFO - [2022-10-09T22:02:31.750+0000] {dagbag.py:330} ERROR - Failed to import: /opt/airflow/dags/desafio-airflow/desafio-indicium.py
Traceback (most recent call last):
  File "/home/airflow/.local/lib/python3.7/site-packages/airflow/models/dagbag.py", line 326, in parse
    loader.exec_module(new_module)
  File "<frozen importlib._bootstrap_external>", line 728, in exec_module
  File "<frozen importlib._bootstrap>", line 219, in _call_with_frames_removed
  File "/opt/airflow/dags/desafio-airflow/desafio-indicium.py", line 4, in <module>
    from scripts.func_le_dados import leitura
ModuleNotFoundError: No module named 'scripts'
[2022-10-09T22:02:31.752+0000] {processor.py:770} WARNING - No viable dags retrieved from /opt/airflow/dags/desafio-airflow/desafio-indicium.py
[2022-10-09T22:02:31.781+0000] {processor.py:178} INFO - Processing /opt/airflow/dags/desafio-airflow/desafio-indicium.py took 0.389 seconds
[2022-10-09T22:03:02.243+0000] {processor.py:156} INFO - Started process (PID=14164) to work on /opt/airflow/dags/desafio-airflow/desafio-indicium.py
[2022-10-09T22:03:02.244+0000] {processor.py:758} INFO - Processing file /opt/airflow/dags/desafio-airflow/desafio-indicium.py for tasks to queue
[2022-10-09T22:03:02.245+0000] {logging_mixin.py:117} INFO - [2022-10-09T22:03:02.245+0000] {dagbag.py:525} INFO - Filling up the DagBag from /opt/airflow/dags/desafio-airflow/desafio-indicium.py
[2022-10-09T22:03:02.547+0000] {logging_mixin.py:117} INFO - [2022-10-09T22:03:02.546+0000] {dagbag.py:330} ERROR - Failed to import: /opt/airflow/dags/desafio-airflow/desafio-indicium.py
Traceback (most recent call last):
  File "/home/airflow/.local/lib/python3.7/site-packages/airflow/models/dagbag.py", line 326, in parse
    loader.exec_module(new_module)
  File "<frozen importlib._bootstrap_external>", line 728, in exec_module
  File "<frozen importlib._bootstrap>", line 219, in _call_with_frames_removed
  File "/opt/airflow/dags/desafio-airflow/desafio-indicium.py", line 4, in <module>
    from scripts.func_le_dados import leitura
ModuleNotFoundError: No module named 'scripts'
[2022-10-09T22:03:02.548+0000] {processor.py:770} WARNING - No viable dags retrieved from /opt/airflow/dags/desafio-airflow/desafio-indicium.py
[2022-10-09T22:03:02.579+0000] {processor.py:178} INFO - Processing /opt/airflow/dags/desafio-airflow/desafio-indicium.py took 0.340 seconds
[2022-10-09T22:03:32.672+0000] {processor.py:156} INFO - Started process (PID=14229) to work on /opt/airflow/dags/desafio-airflow/desafio-indicium.py
[2022-10-09T22:03:32.679+0000] {processor.py:758} INFO - Processing file /opt/airflow/dags/desafio-airflow/desafio-indicium.py for tasks to queue
[2022-10-09T22:03:32.680+0000] {logging_mixin.py:117} INFO - [2022-10-09T22:03:32.680+0000] {dagbag.py:525} INFO - Filling up the DagBag from /opt/airflow/dags/desafio-airflow/desafio-indicium.py
[2022-10-09T22:03:32.984+0000] {logging_mixin.py:117} INFO - [2022-10-09T22:03:32.983+0000] {dagbag.py:330} ERROR - Failed to import: /opt/airflow/dags/desafio-airflow/desafio-indicium.py
Traceback (most recent call last):
  File "/home/airflow/.local/lib/python3.7/site-packages/airflow/models/dagbag.py", line 326, in parse
    loader.exec_module(new_module)
  File "<frozen importlib._bootstrap_external>", line 728, in exec_module
  File "<frozen importlib._bootstrap>", line 219, in _call_with_frames_removed
  File "/opt/airflow/dags/desafio-airflow/desafio-indicium.py", line 4, in <module>
    from scripts.func_le_dados import leitura
ModuleNotFoundError: No module named 'scripts'
[2022-10-09T22:03:32.984+0000] {processor.py:770} WARNING - No viable dags retrieved from /opt/airflow/dags/desafio-airflow/desafio-indicium.py
[2022-10-09T22:03:33.012+0000] {processor.py:178} INFO - Processing /opt/airflow/dags/desafio-airflow/desafio-indicium.py took 0.345 seconds
[2022-10-09T22:04:03.072+0000] {processor.py:156} INFO - Started process (PID=14285) to work on /opt/airflow/dags/desafio-airflow/desafio-indicium.py
[2022-10-09T22:04:03.079+0000] {processor.py:758} INFO - Processing file /opt/airflow/dags/desafio-airflow/desafio-indicium.py for tasks to queue
[2022-10-09T22:04:03.080+0000] {logging_mixin.py:117} INFO - [2022-10-09T22:04:03.079+0000] {dagbag.py:525} INFO - Filling up the DagBag from /opt/airflow/dags/desafio-airflow/desafio-indicium.py
[2022-10-09T22:04:03.299+0000] {logging_mixin.py:117} INFO - [2022-10-09T22:04:03.297+0000] {dagbag.py:330} ERROR - Failed to import: /opt/airflow/dags/desafio-airflow/desafio-indicium.py
Traceback (most recent call last):
  File "/home/airflow/.local/lib/python3.7/site-packages/airflow/models/dagbag.py", line 326, in parse
    loader.exec_module(new_module)
  File "<frozen importlib._bootstrap_external>", line 728, in exec_module
  File "<frozen importlib._bootstrap>", line 219, in _call_with_frames_removed
  File "/opt/airflow/dags/desafio-airflow/desafio-indicium.py", line 4, in <module>
    from scripts.func_le_dados import leitura
ModuleNotFoundError: No module named 'scripts'
[2022-10-09T22:04:03.299+0000] {processor.py:770} WARNING - No viable dags retrieved from /opt/airflow/dags/desafio-airflow/desafio-indicium.py
[2022-10-09T22:04:03.329+0000] {processor.py:178} INFO - Processing /opt/airflow/dags/desafio-airflow/desafio-indicium.py took 0.261 seconds
[2022-10-09T22:04:33.608+0000] {processor.py:156} INFO - Started process (PID=14350) to work on /opt/airflow/dags/desafio-airflow/desafio-indicium.py
[2022-10-09T22:04:33.609+0000] {processor.py:758} INFO - Processing file /opt/airflow/dags/desafio-airflow/desafio-indicium.py for tasks to queue
[2022-10-09T22:04:33.610+0000] {logging_mixin.py:117} INFO - [2022-10-09T22:04:33.610+0000] {dagbag.py:525} INFO - Filling up the DagBag from /opt/airflow/dags/desafio-airflow/desafio-indicium.py
[2022-10-09T22:04:33.973+0000] {logging_mixin.py:117} INFO - [2022-10-09T22:04:33.970+0000] {dagbag.py:330} ERROR - Failed to import: /opt/airflow/dags/desafio-airflow/desafio-indicium.py
Traceback (most recent call last):
  File "/home/airflow/.local/lib/python3.7/site-packages/airflow/models/dagbag.py", line 326, in parse
    loader.exec_module(new_module)
  File "<frozen importlib._bootstrap_external>", line 728, in exec_module
  File "<frozen importlib._bootstrap>", line 219, in _call_with_frames_removed
  File "/opt/airflow/dags/desafio-airflow/desafio-indicium.py", line 4, in <module>
    from scripts.func_le_dados import leitura
ModuleNotFoundError: No module named 'scripts'
[2022-10-09T22:04:33.973+0000] {processor.py:770} WARNING - No viable dags retrieved from /opt/airflow/dags/desafio-airflow/desafio-indicium.py
[2022-10-09T22:04:34.004+0000] {processor.py:178} INFO - Processing /opt/airflow/dags/desafio-airflow/desafio-indicium.py took 0.400 seconds
[2022-10-09T22:05:04.091+0000] {processor.py:156} INFO - Started process (PID=14406) to work on /opt/airflow/dags/desafio-airflow/desafio-indicium.py
[2022-10-09T22:05:04.098+0000] {processor.py:758} INFO - Processing file /opt/airflow/dags/desafio-airflow/desafio-indicium.py for tasks to queue
[2022-10-09T22:05:04.099+0000] {logging_mixin.py:117} INFO - [2022-10-09T22:05:04.099+0000] {dagbag.py:525} INFO - Filling up the DagBag from /opt/airflow/dags/desafio-airflow/desafio-indicium.py
[2022-10-09T22:05:04.464+0000] {logging_mixin.py:117} INFO - [2022-10-09T22:05:04.462+0000] {dagbag.py:330} ERROR - Failed to import: /opt/airflow/dags/desafio-airflow/desafio-indicium.py
Traceback (most recent call last):
  File "/home/airflow/.local/lib/python3.7/site-packages/airflow/models/dagbag.py", line 326, in parse
    loader.exec_module(new_module)
  File "<frozen importlib._bootstrap_external>", line 728, in exec_module
  File "<frozen importlib._bootstrap>", line 219, in _call_with_frames_removed
  File "/opt/airflow/dags/desafio-airflow/desafio-indicium.py", line 4, in <module>
    from scripts.func_le_dados import leitura
ModuleNotFoundError: No module named 'scripts'
[2022-10-09T22:05:04.465+0000] {processor.py:770} WARNING - No viable dags retrieved from /opt/airflow/dags/desafio-airflow/desafio-indicium.py
[2022-10-09T22:05:04.502+0000] {processor.py:178} INFO - Processing /opt/airflow/dags/desafio-airflow/desafio-indicium.py took 0.419 seconds
[2022-10-09T22:05:34.592+0000] {processor.py:156} INFO - Started process (PID=14471) to work on /opt/airflow/dags/desafio-airflow/desafio-indicium.py
[2022-10-09T22:05:34.594+0000] {processor.py:758} INFO - Processing file /opt/airflow/dags/desafio-airflow/desafio-indicium.py for tasks to queue
[2022-10-09T22:05:34.595+0000] {logging_mixin.py:117} INFO - [2022-10-09T22:05:34.595+0000] {dagbag.py:525} INFO - Filling up the DagBag from /opt/airflow/dags/desafio-airflow/desafio-indicium.py
[2022-10-09T22:05:34.988+0000] {logging_mixin.py:117} INFO - [2022-10-09T22:05:34.986+0000] {dagbag.py:330} ERROR - Failed to import: /opt/airflow/dags/desafio-airflow/desafio-indicium.py
Traceback (most recent call last):
  File "/home/airflow/.local/lib/python3.7/site-packages/airflow/models/dagbag.py", line 326, in parse
    loader.exec_module(new_module)
  File "<frozen importlib._bootstrap_external>", line 728, in exec_module
  File "<frozen importlib._bootstrap>", line 219, in _call_with_frames_removed
  File "/opt/airflow/dags/desafio-airflow/desafio-indicium.py", line 4, in <module>
    from scripts.func_le_dados import leitura
ModuleNotFoundError: No module named 'scripts'
[2022-10-09T22:05:34.988+0000] {processor.py:770} WARNING - No viable dags retrieved from /opt/airflow/dags/desafio-airflow/desafio-indicium.py
[2022-10-09T22:05:35.021+0000] {processor.py:178} INFO - Processing /opt/airflow/dags/desafio-airflow/desafio-indicium.py took 0.434 seconds
[2022-10-09T22:06:05.967+0000] {processor.py:156} INFO - Started process (PID=14536) to work on /opt/airflow/dags/desafio-airflow/desafio-indicium.py
[2022-10-09T22:06:05.975+0000] {processor.py:758} INFO - Processing file /opt/airflow/dags/desafio-airflow/desafio-indicium.py for tasks to queue
[2022-10-09T22:06:05.976+0000] {logging_mixin.py:117} INFO - [2022-10-09T22:06:05.975+0000] {dagbag.py:525} INFO - Filling up the DagBag from /opt/airflow/dags/desafio-airflow/desafio-indicium.py
[2022-10-09T22:06:06.336+0000] {logging_mixin.py:117} INFO - [2022-10-09T22:06:06.334+0000] {dagbag.py:330} ERROR - Failed to import: /opt/airflow/dags/desafio-airflow/desafio-indicium.py
Traceback (most recent call last):
  File "/home/airflow/.local/lib/python3.7/site-packages/airflow/models/dagbag.py", line 326, in parse
    loader.exec_module(new_module)
  File "<frozen importlib._bootstrap_external>", line 728, in exec_module
  File "<frozen importlib._bootstrap>", line 219, in _call_with_frames_removed
  File "/opt/airflow/dags/desafio-airflow/desafio-indicium.py", line 4, in <module>
    from scripts.func_le_dados import leitura
ModuleNotFoundError: No module named 'scripts'
[2022-10-09T22:06:06.337+0000] {processor.py:770} WARNING - No viable dags retrieved from /opt/airflow/dags/desafio-airflow/desafio-indicium.py
[2022-10-09T22:06:06.370+0000] {processor.py:178} INFO - Processing /opt/airflow/dags/desafio-airflow/desafio-indicium.py took 0.408 seconds
[2022-10-09T22:06:36.405+0000] {processor.py:156} INFO - Started process (PID=14592) to work on /opt/airflow/dags/desafio-airflow/desafio-indicium.py
[2022-10-09T22:06:36.406+0000] {processor.py:758} INFO - Processing file /opt/airflow/dags/desafio-airflow/desafio-indicium.py for tasks to queue
[2022-10-09T22:06:36.407+0000] {logging_mixin.py:117} INFO - [2022-10-09T22:06:36.407+0000] {dagbag.py:525} INFO - Filling up the DagBag from /opt/airflow/dags/desafio-airflow/desafio-indicium.py
[2022-10-09T22:06:36.691+0000] {logging_mixin.py:117} INFO - [2022-10-09T22:06:36.690+0000] {dagbag.py:330} ERROR - Failed to import: /opt/airflow/dags/desafio-airflow/desafio-indicium.py
Traceback (most recent call last):
  File "/home/airflow/.local/lib/python3.7/site-packages/airflow/models/dagbag.py", line 326, in parse
    loader.exec_module(new_module)
  File "<frozen importlib._bootstrap_external>", line 728, in exec_module
  File "<frozen importlib._bootstrap>", line 219, in _call_with_frames_removed
  File "/opt/airflow/dags/desafio-airflow/desafio-indicium.py", line 4, in <module>
    from scripts.func_le_dados import leitura
ModuleNotFoundError: No module named 'scripts'
[2022-10-09T22:06:36.692+0000] {processor.py:770} WARNING - No viable dags retrieved from /opt/airflow/dags/desafio-airflow/desafio-indicium.py
[2022-10-09T22:06:36.718+0000] {processor.py:178} INFO - Processing /opt/airflow/dags/desafio-airflow/desafio-indicium.py took 0.317 seconds
[2022-10-09T22:07:06.927+0000] {processor.py:156} INFO - Started process (PID=14657) to work on /opt/airflow/dags/desafio-airflow/desafio-indicium.py
[2022-10-09T22:07:06.928+0000] {processor.py:758} INFO - Processing file /opt/airflow/dags/desafio-airflow/desafio-indicium.py for tasks to queue
[2022-10-09T22:07:06.929+0000] {logging_mixin.py:117} INFO - [2022-10-09T22:07:06.929+0000] {dagbag.py:525} INFO - Filling up the DagBag from /opt/airflow/dags/desafio-airflow/desafio-indicium.py
[2022-10-09T22:07:07.256+0000] {logging_mixin.py:117} INFO - [2022-10-09T22:07:07.254+0000] {dagbag.py:330} ERROR - Failed to import: /opt/airflow/dags/desafio-airflow/desafio-indicium.py
Traceback (most recent call last):
  File "/home/airflow/.local/lib/python3.7/site-packages/airflow/models/dagbag.py", line 326, in parse
    loader.exec_module(new_module)
  File "<frozen importlib._bootstrap_external>", line 728, in exec_module
  File "<frozen importlib._bootstrap>", line 219, in _call_with_frames_removed
  File "/opt/airflow/dags/desafio-airflow/desafio-indicium.py", line 4, in <module>
    from scripts.func_le_dados import leitura
ModuleNotFoundError: No module named 'scripts'
[2022-10-09T22:07:07.256+0000] {processor.py:770} WARNING - No viable dags retrieved from /opt/airflow/dags/desafio-airflow/desafio-indicium.py
[2022-10-09T22:07:07.280+0000] {processor.py:178} INFO - Processing /opt/airflow/dags/desafio-airflow/desafio-indicium.py took 0.359 seconds
[2022-10-09T22:07:37.737+0000] {processor.py:156} INFO - Started process (PID=14713) to work on /opt/airflow/dags/desafio-airflow/desafio-indicium.py
[2022-10-09T22:07:37.738+0000] {processor.py:758} INFO - Processing file /opt/airflow/dags/desafio-airflow/desafio-indicium.py for tasks to queue
[2022-10-09T22:07:37.739+0000] {logging_mixin.py:117} INFO - [2022-10-09T22:07:37.738+0000] {dagbag.py:525} INFO - Filling up the DagBag from /opt/airflow/dags/desafio-airflow/desafio-indicium.py
[2022-10-09T22:07:38.114+0000] {logging_mixin.py:117} INFO - [2022-10-09T22:07:38.112+0000] {dagbag.py:330} ERROR - Failed to import: /opt/airflow/dags/desafio-airflow/desafio-indicium.py
Traceback (most recent call last):
  File "/home/airflow/.local/lib/python3.7/site-packages/airflow/models/dagbag.py", line 326, in parse
    loader.exec_module(new_module)
  File "<frozen importlib._bootstrap_external>", line 728, in exec_module
  File "<frozen importlib._bootstrap>", line 219, in _call_with_frames_removed
  File "/opt/airflow/dags/desafio-airflow/desafio-indicium.py", line 4, in <module>
    from scripts.func_le_dados import leitura
ModuleNotFoundError: No module named 'scripts'
[2022-10-09T22:07:38.114+0000] {processor.py:770} WARNING - No viable dags retrieved from /opt/airflow/dags/desafio-airflow/desafio-indicium.py
[2022-10-09T22:07:38.144+0000] {processor.py:178} INFO - Processing /opt/airflow/dags/desafio-airflow/desafio-indicium.py took 0.412 seconds
[2022-10-09T22:08:08.289+0000] {processor.py:156} INFO - Started process (PID=14779) to work on /opt/airflow/dags/desafio-airflow/desafio-indicium.py
[2022-10-09T22:08:08.291+0000] {processor.py:758} INFO - Processing file /opt/airflow/dags/desafio-airflow/desafio-indicium.py for tasks to queue
[2022-10-09T22:08:08.292+0000] {logging_mixin.py:117} INFO - [2022-10-09T22:08:08.292+0000] {dagbag.py:525} INFO - Filling up the DagBag from /opt/airflow/dags/desafio-airflow/desafio-indicium.py
[2022-10-09T22:08:08.644+0000] {logging_mixin.py:117} INFO - [2022-10-09T22:08:08.642+0000] {dagbag.py:330} ERROR - Failed to import: /opt/airflow/dags/desafio-airflow/desafio-indicium.py
Traceback (most recent call last):
  File "/home/airflow/.local/lib/python3.7/site-packages/airflow/models/dagbag.py", line 326, in parse
    loader.exec_module(new_module)
  File "<frozen importlib._bootstrap_external>", line 728, in exec_module
  File "<frozen importlib._bootstrap>", line 219, in _call_with_frames_removed
  File "/opt/airflow/dags/desafio-airflow/desafio-indicium.py", line 4, in <module>
    from scripts.func_le_dados import leitura
ModuleNotFoundError: No module named 'scripts'
[2022-10-09T22:08:08.644+0000] {processor.py:770} WARNING - No viable dags retrieved from /opt/airflow/dags/desafio-airflow/desafio-indicium.py
[2022-10-09T22:08:08.682+0000] {processor.py:178} INFO - Processing /opt/airflow/dags/desafio-airflow/desafio-indicium.py took 0.399 seconds
[2022-10-09T22:08:39.693+0000] {processor.py:156} INFO - Started process (PID=14846) to work on /opt/airflow/dags/desafio-airflow/desafio-indicium.py
[2022-10-09T22:08:39.694+0000] {processor.py:758} INFO - Processing file /opt/airflow/dags/desafio-airflow/desafio-indicium.py for tasks to queue
[2022-10-09T22:08:39.694+0000] {logging_mixin.py:117} INFO - [2022-10-09T22:08:39.694+0000] {dagbag.py:525} INFO - Filling up the DagBag from /opt/airflow/dags/desafio-airflow/desafio-indicium.py
[2022-10-09T22:08:40.080+0000] {logging_mixin.py:117} INFO - [2022-10-09T22:08:40.078+0000] {dagbag.py:330} ERROR - Failed to import: /opt/airflow/dags/desafio-airflow/desafio-indicium.py
Traceback (most recent call last):
  File "/home/airflow/.local/lib/python3.7/site-packages/airflow/models/dagbag.py", line 326, in parse
    loader.exec_module(new_module)
  File "<frozen importlib._bootstrap_external>", line 728, in exec_module
  File "<frozen importlib._bootstrap>", line 219, in _call_with_frames_removed
  File "/opt/airflow/dags/desafio-airflow/desafio-indicium.py", line 4, in <module>
    from scripts.func_le_dados import leitura
ModuleNotFoundError: No module named 'scripts'
[2022-10-09T22:08:40.080+0000] {processor.py:770} WARNING - No viable dags retrieved from /opt/airflow/dags/desafio-airflow/desafio-indicium.py
[2022-10-09T22:08:40.105+0000] {processor.py:178} INFO - Processing /opt/airflow/dags/desafio-airflow/desafio-indicium.py took 0.417 seconds
[2022-10-09T22:09:10.243+0000] {processor.py:156} INFO - Started process (PID=14903) to work on /opt/airflow/dags/desafio-airflow/desafio-indicium.py
[2022-10-09T22:09:10.245+0000] {processor.py:758} INFO - Processing file /opt/airflow/dags/desafio-airflow/desafio-indicium.py for tasks to queue
[2022-10-09T22:09:10.246+0000] {logging_mixin.py:117} INFO - [2022-10-09T22:09:10.245+0000] {dagbag.py:525} INFO - Filling up the DagBag from /opt/airflow/dags/desafio-airflow/desafio-indicium.py
[2022-10-09T22:09:10.559+0000] {logging_mixin.py:117} INFO - [2022-10-09T22:09:10.557+0000] {dagbag.py:330} ERROR - Failed to import: /opt/airflow/dags/desafio-airflow/desafio-indicium.py
Traceback (most recent call last):
  File "/home/airflow/.local/lib/python3.7/site-packages/airflow/models/dagbag.py", line 326, in parse
    loader.exec_module(new_module)
  File "<frozen importlib._bootstrap_external>", line 728, in exec_module
  File "<frozen importlib._bootstrap>", line 219, in _call_with_frames_removed
  File "/opt/airflow/dags/desafio-airflow/desafio-indicium.py", line 4, in <module>
    from scripts.func_le_dados import leitura
ModuleNotFoundError: No module named 'scripts'
[2022-10-09T22:09:10.559+0000] {processor.py:770} WARNING - No viable dags retrieved from /opt/airflow/dags/desafio-airflow/desafio-indicium.py
[2022-10-09T22:09:10.586+0000] {processor.py:178} INFO - Processing /opt/airflow/dags/desafio-airflow/desafio-indicium.py took 0.347 seconds
[2022-10-09T22:09:41.257+0000] {processor.py:156} INFO - Started process (PID=14968) to work on /opt/airflow/dags/desafio-airflow/desafio-indicium.py
[2022-10-09T22:09:41.259+0000] {processor.py:758} INFO - Processing file /opt/airflow/dags/desafio-airflow/desafio-indicium.py for tasks to queue
[2022-10-09T22:09:41.260+0000] {logging_mixin.py:117} INFO - [2022-10-09T22:09:41.259+0000] {dagbag.py:525} INFO - Filling up the DagBag from /opt/airflow/dags/desafio-airflow/desafio-indicium.py
[2022-10-09T22:09:41.569+0000] {logging_mixin.py:117} INFO - [2022-10-09T22:09:41.568+0000] {dagbag.py:330} ERROR - Failed to import: /opt/airflow/dags/desafio-airflow/desafio-indicium.py
Traceback (most recent call last):
  File "/home/airflow/.local/lib/python3.7/site-packages/airflow/models/dagbag.py", line 326, in parse
    loader.exec_module(new_module)
  File "<frozen importlib._bootstrap_external>", line 728, in exec_module
  File "<frozen importlib._bootstrap>", line 219, in _call_with_frames_removed
  File "/opt/airflow/dags/desafio-airflow/desafio-indicium.py", line 4, in <module>
    from scripts.func_le_dados import leitura
ModuleNotFoundError: No module named 'scripts'
[2022-10-09T22:09:41.570+0000] {processor.py:770} WARNING - No viable dags retrieved from /opt/airflow/dags/desafio-airflow/desafio-indicium.py
[2022-10-09T22:09:41.598+0000] {processor.py:178} INFO - Processing /opt/airflow/dags/desafio-airflow/desafio-indicium.py took 0.345 seconds
[2022-10-09T22:10:11.918+0000] {processor.py:156} INFO - Started process (PID=15024) to work on /opt/airflow/dags/desafio-airflow/desafio-indicium.py
[2022-10-09T22:10:11.920+0000] {processor.py:758} INFO - Processing file /opt/airflow/dags/desafio-airflow/desafio-indicium.py for tasks to queue
[2022-10-09T22:10:11.920+0000] {logging_mixin.py:117} INFO - [2022-10-09T22:10:11.920+0000] {dagbag.py:525} INFO - Filling up the DagBag from /opt/airflow/dags/desafio-airflow/desafio-indicium.py
[2022-10-09T22:10:12.257+0000] {logging_mixin.py:117} INFO - [2022-10-09T22:10:12.256+0000] {dagbag.py:330} ERROR - Failed to import: /opt/airflow/dags/desafio-airflow/desafio-indicium.py
Traceback (most recent call last):
  File "/home/airflow/.local/lib/python3.7/site-packages/airflow/models/dagbag.py", line 326, in parse
    loader.exec_module(new_module)
  File "<frozen importlib._bootstrap_external>", line 728, in exec_module
  File "<frozen importlib._bootstrap>", line 219, in _call_with_frames_removed
  File "/opt/airflow/dags/desafio-airflow/desafio-indicium.py", line 4, in <module>
    from scripts.func_le_dados import leitura
ModuleNotFoundError: No module named 'scripts'
[2022-10-09T22:10:12.258+0000] {processor.py:770} WARNING - No viable dags retrieved from /opt/airflow/dags/desafio-airflow/desafio-indicium.py
[2022-10-09T22:10:12.284+0000] {processor.py:178} INFO - Processing /opt/airflow/dags/desafio-airflow/desafio-indicium.py took 0.372 seconds
[2022-10-09T22:10:42.346+0000] {processor.py:156} INFO - Started process (PID=15089) to work on /opt/airflow/dags/desafio-airflow/desafio-indicium.py
[2022-10-09T22:10:42.347+0000] {processor.py:758} INFO - Processing file /opt/airflow/dags/desafio-airflow/desafio-indicium.py for tasks to queue
[2022-10-09T22:10:42.348+0000] {logging_mixin.py:117} INFO - [2022-10-09T22:10:42.348+0000] {dagbag.py:525} INFO - Filling up the DagBag from /opt/airflow/dags/desafio-airflow/desafio-indicium.py
[2022-10-09T22:10:42.686+0000] {logging_mixin.py:117} INFO - [2022-10-09T22:10:42.684+0000] {dagbag.py:330} ERROR - Failed to import: /opt/airflow/dags/desafio-airflow/desafio-indicium.py
Traceback (most recent call last):
  File "/home/airflow/.local/lib/python3.7/site-packages/airflow/models/dagbag.py", line 326, in parse
    loader.exec_module(new_module)
  File "<frozen importlib._bootstrap_external>", line 728, in exec_module
  File "<frozen importlib._bootstrap>", line 219, in _call_with_frames_removed
  File "/opt/airflow/dags/desafio-airflow/desafio-indicium.py", line 4, in <module>
    from scripts.func_le_dados import leitura
ModuleNotFoundError: No module named 'scripts'
[2022-10-09T22:10:42.686+0000] {processor.py:770} WARNING - No viable dags retrieved from /opt/airflow/dags/desafio-airflow/desafio-indicium.py
[2022-10-09T22:10:42.712+0000] {processor.py:178} INFO - Processing /opt/airflow/dags/desafio-airflow/desafio-indicium.py took 0.371 seconds
[2022-10-09T22:11:13.354+0000] {processor.py:156} INFO - Started process (PID=15154) to work on /opt/airflow/dags/desafio-airflow/desafio-indicium.py
[2022-10-09T22:11:13.356+0000] {processor.py:758} INFO - Processing file /opt/airflow/dags/desafio-airflow/desafio-indicium.py for tasks to queue
[2022-10-09T22:11:13.357+0000] {logging_mixin.py:117} INFO - [2022-10-09T22:11:13.357+0000] {dagbag.py:525} INFO - Filling up the DagBag from /opt/airflow/dags/desafio-airflow/desafio-indicium.py
[2022-10-09T22:11:13.675+0000] {logging_mixin.py:117} INFO - [2022-10-09T22:11:13.673+0000] {dagbag.py:330} ERROR - Failed to import: /opt/airflow/dags/desafio-airflow/desafio-indicium.py
Traceback (most recent call last):
  File "/home/airflow/.local/lib/python3.7/site-packages/airflow/models/dagbag.py", line 326, in parse
    loader.exec_module(new_module)
  File "<frozen importlib._bootstrap_external>", line 728, in exec_module
  File "<frozen importlib._bootstrap>", line 219, in _call_with_frames_removed
  File "/opt/airflow/dags/desafio-airflow/desafio-indicium.py", line 4, in <module>
    from scripts.func_le_dados import leitura
ModuleNotFoundError: No module named 'scripts'
[2022-10-09T22:11:13.675+0000] {processor.py:770} WARNING - No viable dags retrieved from /opt/airflow/dags/desafio-airflow/desafio-indicium.py
[2022-10-09T22:11:13.703+0000] {processor.py:178} INFO - Processing /opt/airflow/dags/desafio-airflow/desafio-indicium.py took 0.356 seconds
[2022-10-09T22:11:43.855+0000] {processor.py:156} INFO - Started process (PID=15211) to work on /opt/airflow/dags/desafio-airflow/desafio-indicium.py
[2022-10-09T22:11:43.857+0000] {processor.py:758} INFO - Processing file /opt/airflow/dags/desafio-airflow/desafio-indicium.py for tasks to queue
[2022-10-09T22:11:43.858+0000] {logging_mixin.py:117} INFO - [2022-10-09T22:11:43.858+0000] {dagbag.py:525} INFO - Filling up the DagBag from /opt/airflow/dags/desafio-airflow/desafio-indicium.py
[2022-10-09T22:11:44.175+0000] {logging_mixin.py:117} INFO - [2022-10-09T22:11:44.174+0000] {dagbag.py:330} ERROR - Failed to import: /opt/airflow/dags/desafio-airflow/desafio-indicium.py
Traceback (most recent call last):
  File "/home/airflow/.local/lib/python3.7/site-packages/airflow/models/dagbag.py", line 326, in parse
    loader.exec_module(new_module)
  File "<frozen importlib._bootstrap_external>", line 728, in exec_module
  File "<frozen importlib._bootstrap>", line 219, in _call_with_frames_removed
  File "/opt/airflow/dags/desafio-airflow/desafio-indicium.py", line 4, in <module>
    from scripts.func_le_dados import leitura
ModuleNotFoundError: No module named 'scripts'
[2022-10-09T22:11:44.176+0000] {processor.py:770} WARNING - No viable dags retrieved from /opt/airflow/dags/desafio-airflow/desafio-indicium.py
[2022-10-09T22:11:44.207+0000] {processor.py:178} INFO - Processing /opt/airflow/dags/desafio-airflow/desafio-indicium.py took 0.358 seconds
[2022-10-09T22:12:15.197+0000] {processor.py:156} INFO - Started process (PID=15277) to work on /opt/airflow/dags/desafio-airflow/desafio-indicium.py
[2022-10-09T22:12:15.204+0000] {processor.py:758} INFO - Processing file /opt/airflow/dags/desafio-airflow/desafio-indicium.py for tasks to queue
[2022-10-09T22:12:15.205+0000] {logging_mixin.py:117} INFO - [2022-10-09T22:12:15.205+0000] {dagbag.py:525} INFO - Filling up the DagBag from /opt/airflow/dags/desafio-airflow/desafio-indicium.py
[2022-10-09T22:12:15.508+0000] {logging_mixin.py:117} INFO - [2022-10-09T22:12:15.506+0000] {dagbag.py:330} ERROR - Failed to import: /opt/airflow/dags/desafio-airflow/desafio-indicium.py
Traceback (most recent call last):
  File "/home/airflow/.local/lib/python3.7/site-packages/airflow/models/dagbag.py", line 326, in parse
    loader.exec_module(new_module)
  File "<frozen importlib._bootstrap_external>", line 728, in exec_module
  File "<frozen importlib._bootstrap>", line 219, in _call_with_frames_removed
  File "/opt/airflow/dags/desafio-airflow/desafio-indicium.py", line 4, in <module>
    from scripts.func_le_dados import leitura
ModuleNotFoundError: No module named 'scripts'
[2022-10-09T22:12:15.508+0000] {processor.py:770} WARNING - No viable dags retrieved from /opt/airflow/dags/desafio-airflow/desafio-indicium.py
[2022-10-09T22:12:15.535+0000] {processor.py:178} INFO - Processing /opt/airflow/dags/desafio-airflow/desafio-indicium.py took 0.343 seconds
[2022-10-09T22:12:45.677+0000] {processor.py:156} INFO - Started process (PID=15333) to work on /opt/airflow/dags/desafio-airflow/desafio-indicium.py
[2022-10-09T22:12:45.679+0000] {processor.py:758} INFO - Processing file /opt/airflow/dags/desafio-airflow/desafio-indicium.py for tasks to queue
[2022-10-09T22:12:45.680+0000] {logging_mixin.py:117} INFO - [2022-10-09T22:12:45.679+0000] {dagbag.py:525} INFO - Filling up the DagBag from /opt/airflow/dags/desafio-airflow/desafio-indicium.py
[2022-10-09T22:12:46.140+0000] {logging_mixin.py:117} INFO - [2022-10-09T22:12:46.138+0000] {dagbag.py:330} ERROR - Failed to import: /opt/airflow/dags/desafio-airflow/desafio-indicium.py
Traceback (most recent call last):
  File "/home/airflow/.local/lib/python3.7/site-packages/airflow/models/dagbag.py", line 326, in parse
    loader.exec_module(new_module)
  File "<frozen importlib._bootstrap_external>", line 728, in exec_module
  File "<frozen importlib._bootstrap>", line 219, in _call_with_frames_removed
  File "/opt/airflow/dags/desafio-airflow/desafio-indicium.py", line 4, in <module>
    from scripts.func_le_dados import leitura
ModuleNotFoundError: No module named 'scripts'
[2022-10-09T22:12:46.141+0000] {processor.py:770} WARNING - No viable dags retrieved from /opt/airflow/dags/desafio-airflow/desafio-indicium.py
[2022-10-09T22:12:46.180+0000] {processor.py:178} INFO - Processing /opt/airflow/dags/desafio-airflow/desafio-indicium.py took 0.507 seconds
[2022-10-09T22:13:16.308+0000] {processor.py:156} INFO - Started process (PID=15399) to work on /opt/airflow/dags/desafio-airflow/desafio-indicium.py
[2022-10-09T22:13:16.309+0000] {processor.py:758} INFO - Processing file /opt/airflow/dags/desafio-airflow/desafio-indicium.py for tasks to queue
[2022-10-09T22:13:16.310+0000] {logging_mixin.py:117} INFO - [2022-10-09T22:13:16.310+0000] {dagbag.py:525} INFO - Filling up the DagBag from /opt/airflow/dags/desafio-airflow/desafio-indicium.py
[2022-10-09T22:13:16.616+0000] {logging_mixin.py:117} INFO - [2022-10-09T22:13:16.614+0000] {dagbag.py:330} ERROR - Failed to import: /opt/airflow/dags/desafio-airflow/desafio-indicium.py
Traceback (most recent call last):
  File "/home/airflow/.local/lib/python3.7/site-packages/airflow/models/dagbag.py", line 326, in parse
    loader.exec_module(new_module)
  File "<frozen importlib._bootstrap_external>", line 728, in exec_module
  File "<frozen importlib._bootstrap>", line 219, in _call_with_frames_removed
  File "/opt/airflow/dags/desafio-airflow/desafio-indicium.py", line 4, in <module>
    from scripts.func_le_dados import leitura
ModuleNotFoundError: No module named 'scripts'
[2022-10-09T22:13:16.616+0000] {processor.py:770} WARNING - No viable dags retrieved from /opt/airflow/dags/desafio-airflow/desafio-indicium.py
[2022-10-09T22:13:16.642+0000] {processor.py:178} INFO - Processing /opt/airflow/dags/desafio-airflow/desafio-indicium.py took 0.341 seconds
[2022-10-09T22:13:46.826+0000] {processor.py:156} INFO - Started process (PID=15464) to work on /opt/airflow/dags/desafio-airflow/desafio-indicium.py
[2022-10-09T22:13:46.827+0000] {processor.py:758} INFO - Processing file /opt/airflow/dags/desafio-airflow/desafio-indicium.py for tasks to queue
[2022-10-09T22:13:46.828+0000] {logging_mixin.py:117} INFO - [2022-10-09T22:13:46.828+0000] {dagbag.py:525} INFO - Filling up the DagBag from /opt/airflow/dags/desafio-airflow/desafio-indicium.py
[2022-10-09T22:13:47.163+0000] {logging_mixin.py:117} INFO - [2022-10-09T22:13:47.162+0000] {dagbag.py:330} ERROR - Failed to import: /opt/airflow/dags/desafio-airflow/desafio-indicium.py
Traceback (most recent call last):
  File "/home/airflow/.local/lib/python3.7/site-packages/airflow/models/dagbag.py", line 326, in parse
    loader.exec_module(new_module)
  File "<frozen importlib._bootstrap_external>", line 728, in exec_module
  File "<frozen importlib._bootstrap>", line 219, in _call_with_frames_removed
  File "/opt/airflow/dags/desafio-airflow/desafio-indicium.py", line 4, in <module>
    from scripts.func_le_dados import leitura
ModuleNotFoundError: No module named 'scripts'
[2022-10-09T22:13:47.164+0000] {processor.py:770} WARNING - No viable dags retrieved from /opt/airflow/dags/desafio-airflow/desafio-indicium.py
[2022-10-09T22:13:47.193+0000] {processor.py:178} INFO - Processing /opt/airflow/dags/desafio-airflow/desafio-indicium.py took 0.370 seconds
[2022-10-09T22:14:18.215+0000] {processor.py:156} INFO - Started process (PID=15520) to work on /opt/airflow/dags/desafio-airflow/desafio-indicium.py
[2022-10-09T22:14:18.219+0000] {processor.py:758} INFO - Processing file /opt/airflow/dags/desafio-airflow/desafio-indicium.py for tasks to queue
[2022-10-09T22:14:18.219+0000] {logging_mixin.py:117} INFO - [2022-10-09T22:14:18.219+0000] {dagbag.py:525} INFO - Filling up the DagBag from /opt/airflow/dags/desafio-airflow/desafio-indicium.py
[2022-10-09T22:14:18.586+0000] {logging_mixin.py:117} INFO - [2022-10-09T22:14:18.584+0000] {dagbag.py:330} ERROR - Failed to import: /opt/airflow/dags/desafio-airflow/desafio-indicium.py
Traceback (most recent call last):
  File "/home/airflow/.local/lib/python3.7/site-packages/airflow/models/dagbag.py", line 326, in parse
    loader.exec_module(new_module)
  File "<frozen importlib._bootstrap_external>", line 728, in exec_module
  File "<frozen importlib._bootstrap>", line 219, in _call_with_frames_removed
  File "/opt/airflow/dags/desafio-airflow/desafio-indicium.py", line 4, in <module>
    from scripts.func_le_dados import leitura
ModuleNotFoundError: No module named 'scripts'
[2022-10-09T22:14:18.587+0000] {processor.py:770} WARNING - No viable dags retrieved from /opt/airflow/dags/desafio-airflow/desafio-indicium.py
[2022-10-09T22:14:18.620+0000] {processor.py:178} INFO - Processing /opt/airflow/dags/desafio-airflow/desafio-indicium.py took 0.411 seconds
[2022-10-09T22:14:48.771+0000] {processor.py:156} INFO - Started process (PID=15586) to work on /opt/airflow/dags/desafio-airflow/desafio-indicium.py
[2022-10-09T22:14:48.773+0000] {processor.py:758} INFO - Processing file /opt/airflow/dags/desafio-airflow/desafio-indicium.py for tasks to queue
[2022-10-09T22:14:48.774+0000] {logging_mixin.py:117} INFO - [2022-10-09T22:14:48.773+0000] {dagbag.py:525} INFO - Filling up the DagBag from /opt/airflow/dags/desafio-airflow/desafio-indicium.py
[2022-10-09T22:14:49.131+0000] {logging_mixin.py:117} INFO - [2022-10-09T22:14:49.129+0000] {dagbag.py:330} ERROR - Failed to import: /opt/airflow/dags/desafio-airflow/desafio-indicium.py
Traceback (most recent call last):
  File "/home/airflow/.local/lib/python3.7/site-packages/airflow/models/dagbag.py", line 326, in parse
    loader.exec_module(new_module)
  File "<frozen importlib._bootstrap_external>", line 728, in exec_module
  File "<frozen importlib._bootstrap>", line 219, in _call_with_frames_removed
  File "/opt/airflow/dags/desafio-airflow/desafio-indicium.py", line 4, in <module>
    from scripts.func_le_dados import leitura
ModuleNotFoundError: No module named 'scripts'
[2022-10-09T22:14:49.131+0000] {processor.py:770} WARNING - No viable dags retrieved from /opt/airflow/dags/desafio-airflow/desafio-indicium.py
[2022-10-09T22:14:49.159+0000] {processor.py:178} INFO - Processing /opt/airflow/dags/desafio-airflow/desafio-indicium.py took 0.393 seconds
[2022-10-09T22:15:19.473+0000] {processor.py:156} INFO - Started process (PID=15644) to work on /opt/airflow/dags/desafio-airflow/desafio-indicium.py
[2022-10-09T22:15:19.475+0000] {processor.py:758} INFO - Processing file /opt/airflow/dags/desafio-airflow/desafio-indicium.py for tasks to queue
[2022-10-09T22:15:19.476+0000] {logging_mixin.py:117} INFO - [2022-10-09T22:15:19.475+0000] {dagbag.py:525} INFO - Filling up the DagBag from /opt/airflow/dags/desafio-airflow/desafio-indicium.py
[2022-10-09T22:15:19.891+0000] {logging_mixin.py:117} INFO - [2022-10-09T22:15:19.889+0000] {dagbag.py:330} ERROR - Failed to import: /opt/airflow/dags/desafio-airflow/desafio-indicium.py
Traceback (most recent call last):
  File "/home/airflow/.local/lib/python3.7/site-packages/airflow/models/dagbag.py", line 326, in parse
    loader.exec_module(new_module)
  File "<frozen importlib._bootstrap_external>", line 728, in exec_module
  File "<frozen importlib._bootstrap>", line 219, in _call_with_frames_removed
  File "/opt/airflow/dags/desafio-airflow/desafio-indicium.py", line 4, in <module>
    from scripts.func_le_dados import leitura
ModuleNotFoundError: No module named 'scripts'
[2022-10-09T22:15:19.892+0000] {processor.py:770} WARNING - No viable dags retrieved from /opt/airflow/dags/desafio-airflow/desafio-indicium.py
[2022-10-09T22:15:19.919+0000] {processor.py:178} INFO - Processing /opt/airflow/dags/desafio-airflow/desafio-indicium.py took 0.452 seconds
[2022-10-09T22:15:50.001+0000] {processor.py:156} INFO - Started process (PID=15711) to work on /opt/airflow/dags/desafio-airflow/desafio-indicium.py
[2022-10-09T22:15:50.002+0000] {processor.py:758} INFO - Processing file /opt/airflow/dags/desafio-airflow/desafio-indicium.py for tasks to queue
[2022-10-09T22:15:50.003+0000] {logging_mixin.py:117} INFO - [2022-10-09T22:15:50.003+0000] {dagbag.py:525} INFO - Filling up the DagBag from /opt/airflow/dags/desafio-airflow/desafio-indicium.py
[2022-10-09T22:15:50.282+0000] {logging_mixin.py:117} INFO - [2022-10-09T22:15:50.281+0000] {dagbag.py:330} ERROR - Failed to import: /opt/airflow/dags/desafio-airflow/desafio-indicium.py
Traceback (most recent call last):
  File "/home/airflow/.local/lib/python3.7/site-packages/airflow/models/dagbag.py", line 326, in parse
    loader.exec_module(new_module)
  File "<frozen importlib._bootstrap_external>", line 728, in exec_module
  File "<frozen importlib._bootstrap>", line 219, in _call_with_frames_removed
  File "/opt/airflow/dags/desafio-airflow/desafio-indicium.py", line 4, in <module>
    from scripts.func_le_dados import leitura
ModuleNotFoundError: No module named 'scripts'
[2022-10-09T22:15:50.282+0000] {processor.py:770} WARNING - No viable dags retrieved from /opt/airflow/dags/desafio-airflow/desafio-indicium.py
[2022-10-09T22:15:50.314+0000] {processor.py:178} INFO - Processing /opt/airflow/dags/desafio-airflow/desafio-indicium.py took 0.318 seconds
[2022-10-09T22:16:21.136+0000] {processor.py:156} INFO - Started process (PID=15776) to work on /opt/airflow/dags/desafio-airflow/desafio-indicium.py
[2022-10-09T22:16:21.137+0000] {processor.py:758} INFO - Processing file /opt/airflow/dags/desafio-airflow/desafio-indicium.py for tasks to queue
[2022-10-09T22:16:21.138+0000] {logging_mixin.py:117} INFO - [2022-10-09T22:16:21.138+0000] {dagbag.py:525} INFO - Filling up the DagBag from /opt/airflow/dags/desafio-airflow/desafio-indicium.py
[2022-10-09T22:16:21.488+0000] {logging_mixin.py:117} INFO - [2022-10-09T22:16:21.486+0000] {dagbag.py:330} ERROR - Failed to import: /opt/airflow/dags/desafio-airflow/desafio-indicium.py
Traceback (most recent call last):
  File "/home/airflow/.local/lib/python3.7/site-packages/airflow/models/dagbag.py", line 326, in parse
    loader.exec_module(new_module)
  File "<frozen importlib._bootstrap_external>", line 728, in exec_module
  File "<frozen importlib._bootstrap>", line 219, in _call_with_frames_removed
  File "/opt/airflow/dags/desafio-airflow/desafio-indicium.py", line 4, in <module>
    from scripts.func_le_dados import leitura
ModuleNotFoundError: No module named 'scripts'
[2022-10-09T22:16:21.488+0000] {processor.py:770} WARNING - No viable dags retrieved from /opt/airflow/dags/desafio-airflow/desafio-indicium.py
[2022-10-09T22:16:21.519+0000] {processor.py:178} INFO - Processing /opt/airflow/dags/desafio-airflow/desafio-indicium.py took 0.387 seconds
[2022-10-09T22:16:51.587+0000] {processor.py:156} INFO - Started process (PID=15832) to work on /opt/airflow/dags/desafio-airflow/desafio-indicium.py
[2022-10-09T22:16:51.588+0000] {processor.py:758} INFO - Processing file /opt/airflow/dags/desafio-airflow/desafio-indicium.py for tasks to queue
[2022-10-09T22:16:51.588+0000] {logging_mixin.py:117} INFO - [2022-10-09T22:16:51.588+0000] {dagbag.py:525} INFO - Filling up the DagBag from /opt/airflow/dags/desafio-airflow/desafio-indicium.py
[2022-10-09T22:16:51.855+0000] {logging_mixin.py:117} INFO - [2022-10-09T22:16:51.854+0000] {dagbag.py:330} ERROR - Failed to import: /opt/airflow/dags/desafio-airflow/desafio-indicium.py
Traceback (most recent call last):
  File "/home/airflow/.local/lib/python3.7/site-packages/airflow/models/dagbag.py", line 326, in parse
    loader.exec_module(new_module)
  File "<frozen importlib._bootstrap_external>", line 728, in exec_module
  File "<frozen importlib._bootstrap>", line 219, in _call_with_frames_removed
  File "/opt/airflow/dags/desafio-airflow/desafio-indicium.py", line 4, in <module>
    from scripts.func_le_dados import leitura
ModuleNotFoundError: No module named 'scripts'
[2022-10-09T22:16:51.856+0000] {processor.py:770} WARNING - No viable dags retrieved from /opt/airflow/dags/desafio-airflow/desafio-indicium.py
[2022-10-09T22:16:51.889+0000] {processor.py:178} INFO - Processing /opt/airflow/dags/desafio-airflow/desafio-indicium.py took 0.310 seconds
[2022-10-09T22:17:22.396+0000] {processor.py:156} INFO - Started process (PID=15897) to work on /opt/airflow/dags/desafio-airflow/desafio-indicium.py
[2022-10-09T22:17:22.398+0000] {processor.py:758} INFO - Processing file /opt/airflow/dags/desafio-airflow/desafio-indicium.py for tasks to queue
[2022-10-09T22:17:22.399+0000] {logging_mixin.py:117} INFO - [2022-10-09T22:17:22.399+0000] {dagbag.py:525} INFO - Filling up the DagBag from /opt/airflow/dags/desafio-airflow/desafio-indicium.py
[2022-10-09T22:17:22.955+0000] {logging_mixin.py:117} INFO - [2022-10-09T22:17:22.953+0000] {dagbag.py:330} ERROR - Failed to import: /opt/airflow/dags/desafio-airflow/desafio-indicium.py
Traceback (most recent call last):
  File "/home/airflow/.local/lib/python3.7/site-packages/airflow/models/dagbag.py", line 326, in parse
    loader.exec_module(new_module)
  File "<frozen importlib._bootstrap_external>", line 728, in exec_module
  File "<frozen importlib._bootstrap>", line 219, in _call_with_frames_removed
  File "/opt/airflow/dags/desafio-airflow/desafio-indicium.py", line 4, in <module>
    from scripts.func_le_dados import leitura
ModuleNotFoundError: No module named 'scripts'
[2022-10-09T22:17:22.956+0000] {processor.py:770} WARNING - No viable dags retrieved from /opt/airflow/dags/desafio-airflow/desafio-indicium.py
[2022-10-09T22:17:22.995+0000] {processor.py:178} INFO - Processing /opt/airflow/dags/desafio-airflow/desafio-indicium.py took 0.603 seconds
[2022-10-09T22:17:54.025+0000] {processor.py:156} INFO - Started process (PID=15953) to work on /opt/airflow/dags/desafio-airflow/desafio-indicium.py
[2022-10-09T22:17:54.026+0000] {processor.py:758} INFO - Processing file /opt/airflow/dags/desafio-airflow/desafio-indicium.py for tasks to queue
[2022-10-09T22:17:54.027+0000] {logging_mixin.py:117} INFO - [2022-10-09T22:17:54.027+0000] {dagbag.py:525} INFO - Filling up the DagBag from /opt/airflow/dags/desafio-airflow/desafio-indicium.py
[2022-10-09T22:17:54.286+0000] {logging_mixin.py:117} INFO - [2022-10-09T22:17:54.284+0000] {dagbag.py:330} ERROR - Failed to import: /opt/airflow/dags/desafio-airflow/desafio-indicium.py
Traceback (most recent call last):
  File "/home/airflow/.local/lib/python3.7/site-packages/airflow/models/dagbag.py", line 326, in parse
    loader.exec_module(new_module)
  File "<frozen importlib._bootstrap_external>", line 728, in exec_module
  File "<frozen importlib._bootstrap>", line 219, in _call_with_frames_removed
  File "/opt/airflow/dags/desafio-airflow/desafio-indicium.py", line 4, in <module>
    from scripts.func_le_dados import leitura
ModuleNotFoundError: No module named 'scripts'
[2022-10-09T22:17:54.287+0000] {processor.py:770} WARNING - No viable dags retrieved from /opt/airflow/dags/desafio-airflow/desafio-indicium.py
[2022-10-09T22:17:54.317+0000] {processor.py:178} INFO - Processing /opt/airflow/dags/desafio-airflow/desafio-indicium.py took 0.297 seconds
[2022-10-09T22:18:24.805+0000] {processor.py:156} INFO - Started process (PID=16017) to work on /opt/airflow/dags/desafio-airflow/desafio-indicium.py
[2022-10-09T22:18:24.812+0000] {processor.py:758} INFO - Processing file /opt/airflow/dags/desafio-airflow/desafio-indicium.py for tasks to queue
[2022-10-09T22:18:24.813+0000] {logging_mixin.py:117} INFO - [2022-10-09T22:18:24.812+0000] {dagbag.py:525} INFO - Filling up the DagBag from /opt/airflow/dags/desafio-airflow/desafio-indicium.py
[2022-10-09T22:18:25.112+0000] {logging_mixin.py:117} INFO - [2022-10-09T22:18:25.111+0000] {dagbag.py:330} ERROR - Failed to import: /opt/airflow/dags/desafio-airflow/desafio-indicium.py
Traceback (most recent call last):
  File "/home/airflow/.local/lib/python3.7/site-packages/airflow/models/dagbag.py", line 326, in parse
    loader.exec_module(new_module)
  File "<frozen importlib._bootstrap_external>", line 728, in exec_module
  File "<frozen importlib._bootstrap>", line 219, in _call_with_frames_removed
  File "/opt/airflow/dags/desafio-airflow/desafio-indicium.py", line 4, in <module>
    from scripts.func_le_dados import leitura
ModuleNotFoundError: No module named 'scripts'
[2022-10-09T22:18:25.112+0000] {processor.py:770} WARNING - No viable dags retrieved from /opt/airflow/dags/desafio-airflow/desafio-indicium.py
[2022-10-09T22:18:25.147+0000] {processor.py:178} INFO - Processing /opt/airflow/dags/desafio-airflow/desafio-indicium.py took 0.347 seconds
[2022-10-09T22:18:55.409+0000] {processor.py:156} INFO - Started process (PID=16073) to work on /opt/airflow/dags/desafio-airflow/desafio-indicium.py
[2022-10-09T22:18:55.416+0000] {processor.py:758} INFO - Processing file /opt/airflow/dags/desafio-airflow/desafio-indicium.py for tasks to queue
[2022-10-09T22:18:55.418+0000] {logging_mixin.py:117} INFO - [2022-10-09T22:18:55.417+0000] {dagbag.py:525} INFO - Filling up the DagBag from /opt/airflow/dags/desafio-airflow/desafio-indicium.py
[2022-10-09T22:18:55.693+0000] {logging_mixin.py:117} INFO - [2022-10-09T22:18:55.691+0000] {dagbag.py:330} ERROR - Failed to import: /opt/airflow/dags/desafio-airflow/desafio-indicium.py
Traceback (most recent call last):
  File "/home/airflow/.local/lib/python3.7/site-packages/airflow/models/dagbag.py", line 326, in parse
    loader.exec_module(new_module)
  File "<frozen importlib._bootstrap_external>", line 728, in exec_module
  File "<frozen importlib._bootstrap>", line 219, in _call_with_frames_removed
  File "/opt/airflow/dags/desafio-airflow/desafio-indicium.py", line 4, in <module>
    from scripts.func_le_dados import leitura
ModuleNotFoundError: No module named 'scripts'
[2022-10-09T22:18:55.693+0000] {processor.py:770} WARNING - No viable dags retrieved from /opt/airflow/dags/desafio-airflow/desafio-indicium.py
[2022-10-09T22:18:55.728+0000] {processor.py:178} INFO - Processing /opt/airflow/dags/desafio-airflow/desafio-indicium.py took 0.325 seconds
[2022-10-09T22:19:26.605+0000] {processor.py:156} INFO - Started process (PID=16138) to work on /opt/airflow/dags/desafio-airflow/desafio-indicium.py
[2022-10-09T22:19:26.607+0000] {processor.py:758} INFO - Processing file /opt/airflow/dags/desafio-airflow/desafio-indicium.py for tasks to queue
[2022-10-09T22:19:26.608+0000] {logging_mixin.py:117} INFO - [2022-10-09T22:19:26.608+0000] {dagbag.py:525} INFO - Filling up the DagBag from /opt/airflow/dags/desafio-airflow/desafio-indicium.py
[2022-10-09T22:19:26.924+0000] {logging_mixin.py:117} INFO - [2022-10-09T22:19:26.922+0000] {dagbag.py:330} ERROR - Failed to import: /opt/airflow/dags/desafio-airflow/desafio-indicium.py
Traceback (most recent call last):
  File "/home/airflow/.local/lib/python3.7/site-packages/airflow/models/dagbag.py", line 326, in parse
    loader.exec_module(new_module)
  File "<frozen importlib._bootstrap_external>", line 728, in exec_module
  File "<frozen importlib._bootstrap>", line 219, in _call_with_frames_removed
  File "/opt/airflow/dags/desafio-airflow/desafio-indicium.py", line 4, in <module>
    from scripts.func_le_dados import leitura
ModuleNotFoundError: No module named 'scripts'
[2022-10-09T22:19:26.924+0000] {processor.py:770} WARNING - No viable dags retrieved from /opt/airflow/dags/desafio-airflow/desafio-indicium.py
[2022-10-09T22:19:26.959+0000] {processor.py:178} INFO - Processing /opt/airflow/dags/desafio-airflow/desafio-indicium.py took 0.358 seconds
[2022-10-09T22:19:57.600+0000] {processor.py:156} INFO - Started process (PID=16194) to work on /opt/airflow/dags/desafio-airflow/desafio-indicium.py
[2022-10-09T22:19:57.601+0000] {processor.py:758} INFO - Processing file /opt/airflow/dags/desafio-airflow/desafio-indicium.py for tasks to queue
[2022-10-09T22:19:57.602+0000] {logging_mixin.py:117} INFO - [2022-10-09T22:19:57.601+0000] {dagbag.py:525} INFO - Filling up the DagBag from /opt/airflow/dags/desafio-airflow/desafio-indicium.py
[2022-10-09T22:19:57.906+0000] {logging_mixin.py:117} INFO - [2022-10-09T22:19:57.904+0000] {dagbag.py:330} ERROR - Failed to import: /opt/airflow/dags/desafio-airflow/desafio-indicium.py
Traceback (most recent call last):
  File "/home/airflow/.local/lib/python3.7/site-packages/airflow/models/dagbag.py", line 326, in parse
    loader.exec_module(new_module)
  File "<frozen importlib._bootstrap_external>", line 728, in exec_module
  File "<frozen importlib._bootstrap>", line 219, in _call_with_frames_removed
  File "/opt/airflow/dags/desafio-airflow/desafio-indicium.py", line 4, in <module>
    from scripts.func_le_dados import leitura
ModuleNotFoundError: No module named 'scripts'
[2022-10-09T22:19:57.907+0000] {processor.py:770} WARNING - No viable dags retrieved from /opt/airflow/dags/desafio-airflow/desafio-indicium.py
[2022-10-09T22:19:57.942+0000] {processor.py:178} INFO - Processing /opt/airflow/dags/desafio-airflow/desafio-indicium.py took 0.345 seconds
[2022-10-09T22:20:28.439+0000] {processor.py:156} INFO - Started process (PID=16259) to work on /opt/airflow/dags/desafio-airflow/desafio-indicium.py
[2022-10-09T22:20:28.446+0000] {processor.py:758} INFO - Processing file /opt/airflow/dags/desafio-airflow/desafio-indicium.py for tasks to queue
[2022-10-09T22:20:28.447+0000] {logging_mixin.py:117} INFO - [2022-10-09T22:20:28.446+0000] {dagbag.py:525} INFO - Filling up the DagBag from /opt/airflow/dags/desafio-airflow/desafio-indicium.py
[2022-10-09T22:20:28.831+0000] {logging_mixin.py:117} INFO - [2022-10-09T22:20:28.829+0000] {dagbag.py:330} ERROR - Failed to import: /opt/airflow/dags/desafio-airflow/desafio-indicium.py
Traceback (most recent call last):
  File "/home/airflow/.local/lib/python3.7/site-packages/airflow/models/dagbag.py", line 326, in parse
    loader.exec_module(new_module)
  File "<frozen importlib._bootstrap_external>", line 728, in exec_module
  File "<frozen importlib._bootstrap>", line 219, in _call_with_frames_removed
  File "/opt/airflow/dags/desafio-airflow/desafio-indicium.py", line 4, in <module>
    from scripts.func_le_dados import leitura
ModuleNotFoundError: No module named 'scripts'
[2022-10-09T22:20:28.831+0000] {processor.py:770} WARNING - No viable dags retrieved from /opt/airflow/dags/desafio-airflow/desafio-indicium.py
[2022-10-09T22:20:28.866+0000] {processor.py:178} INFO - Processing /opt/airflow/dags/desafio-airflow/desafio-indicium.py took 0.434 seconds
[2022-10-09T22:20:59.672+0000] {processor.py:156} INFO - Started process (PID=16323) to work on /opt/airflow/dags/desafio-airflow/desafio-indicium.py
[2022-10-09T22:20:59.673+0000] {processor.py:758} INFO - Processing file /opt/airflow/dags/desafio-airflow/desafio-indicium.py for tasks to queue
[2022-10-09T22:20:59.675+0000] {logging_mixin.py:117} INFO - [2022-10-09T22:20:59.674+0000] {dagbag.py:525} INFO - Filling up the DagBag from /opt/airflow/dags/desafio-airflow/desafio-indicium.py
[2022-10-09T22:21:00.194+0000] {logging_mixin.py:117} INFO - [2022-10-09T22:21:00.191+0000] {dagbag.py:330} ERROR - Failed to import: /opt/airflow/dags/desafio-airflow/desafio-indicium.py
Traceback (most recent call last):
  File "/home/airflow/.local/lib/python3.7/site-packages/airflow/models/dagbag.py", line 326, in parse
    loader.exec_module(new_module)
  File "<frozen importlib._bootstrap_external>", line 728, in exec_module
  File "<frozen importlib._bootstrap>", line 219, in _call_with_frames_removed
  File "/opt/airflow/dags/desafio-airflow/desafio-indicium.py", line 4, in <module>
    from scripts.func_le_dados import leitura
ModuleNotFoundError: No module named 'scripts'
[2022-10-09T22:21:00.195+0000] {processor.py:770} WARNING - No viable dags retrieved from /opt/airflow/dags/desafio-airflow/desafio-indicium.py
[2022-10-09T22:21:00.226+0000] {processor.py:178} INFO - Processing /opt/airflow/dags/desafio-airflow/desafio-indicium.py took 0.559 seconds
[2022-10-09T22:21:11.187+0000] {processor.py:156} INFO - Started process (PID=16330) to work on /opt/airflow/dags/desafio-airflow/desafio-indicium.py
[2022-10-09T22:21:11.188+0000] {processor.py:758} INFO - Processing file /opt/airflow/dags/desafio-airflow/desafio-indicium.py for tasks to queue
[2022-10-09T22:21:11.189+0000] {logging_mixin.py:117} INFO - [2022-10-09T22:21:11.189+0000] {dagbag.py:525} INFO - Filling up the DagBag from /opt/airflow/dags/desafio-airflow/desafio-indicium.py
[2022-10-09T22:21:11.561+0000] {logging_mixin.py:117} INFO - [2022-10-09T22:21:11.558+0000] {dagbag.py:330} ERROR - Failed to import: /opt/airflow/dags/desafio-airflow/desafio-indicium.py
Traceback (most recent call last):
  File "/home/airflow/.local/lib/python3.7/site-packages/airflow/models/dagbag.py", line 326, in parse
    loader.exec_module(new_module)
  File "<frozen importlib._bootstrap_external>", line 728, in exec_module
  File "<frozen importlib._bootstrap>", line 219, in _call_with_frames_removed
  File "/opt/airflow/dags/desafio-airflow/desafio-indicium.py", line 4, in <module>
    from func_le_dados import leitura
ModuleNotFoundError: No module named 'func_le_dados'
[2022-10-09T22:21:11.561+0000] {processor.py:770} WARNING - No viable dags retrieved from /opt/airflow/dags/desafio-airflow/desafio-indicium.py
[2022-10-09T22:21:11.589+0000] {processor.py:178} INFO - Processing /opt/airflow/dags/desafio-airflow/desafio-indicium.py took 0.408 seconds
[2022-10-09T22:21:23.406+0000] {processor.py:156} INFO - Started process (PID=16367) to work on /opt/airflow/dags/desafio-airflow/desafio-indicium.py
[2022-10-09T22:21:23.408+0000] {processor.py:758} INFO - Processing file /opt/airflow/dags/desafio-airflow/desafio-indicium.py for tasks to queue
[2022-10-09T22:21:23.409+0000] {logging_mixin.py:117} INFO - [2022-10-09T22:21:23.409+0000] {dagbag.py:525} INFO - Filling up the DagBag from /opt/airflow/dags/desafio-airflow/desafio-indicium.py
[2022-10-09T22:21:23.412+0000] {logging_mixin.py:117} INFO - [2022-10-09T22:21:23.411+0000] {dagbag.py:330} ERROR - Failed to import: /opt/airflow/dags/desafio-airflow/desafio-indicium.py
Traceback (most recent call last):
  File "/home/airflow/.local/lib/python3.7/site-packages/airflow/models/dagbag.py", line 326, in parse
    loader.exec_module(new_module)
  File "<frozen importlib._bootstrap_external>", line 724, in exec_module
  File "<frozen importlib._bootstrap_external>", line 860, in get_code
  File "<frozen importlib._bootstrap_external>", line 791, in source_to_code
  File "<frozen importlib._bootstrap>", line 219, in _call_with_frames_removed
  File "/opt/airflow/dags/desafio-airflow/desafio-indicium.py", line 22
    dag_id = 'desafio-indicium',
         ^
SyntaxError: invalid syntax
[2022-10-09T22:21:23.412+0000] {processor.py:770} WARNING - No viable dags retrieved from /opt/airflow/dags/desafio-airflow/desafio-indicium.py
[2022-10-09T22:21:23.442+0000] {processor.py:178} INFO - Processing /opt/airflow/dags/desafio-airflow/desafio-indicium.py took 0.042 seconds
[2022-10-09T22:21:49.963+0000] {processor.py:156} INFO - Started process (PID=16413) to work on /opt/airflow/dags/desafio-airflow/desafio-indicium.py
[2022-10-09T22:21:49.964+0000] {processor.py:758} INFO - Processing file /opt/airflow/dags/desafio-airflow/desafio-indicium.py for tasks to queue
[2022-10-09T22:21:49.965+0000] {logging_mixin.py:117} INFO - [2022-10-09T22:21:49.965+0000] {dagbag.py:525} INFO - Filling up the DagBag from /opt/airflow/dags/desafio-airflow/desafio-indicium.py
[2022-10-09T22:21:50.386+0000] {logging_mixin.py:117} INFO - [2022-10-09T22:21:50.382+0000] {dagbag.py:330} ERROR - Failed to import: /opt/airflow/dags/desafio-airflow/desafio-indicium.py
Traceback (most recent call last):
  File "/home/airflow/.local/lib/python3.7/site-packages/airflow/models/dagbag.py", line 326, in parse
    loader.exec_module(new_module)
  File "<frozen importlib._bootstrap_external>", line 728, in exec_module
  File "<frozen importlib._bootstrap>", line 219, in _call_with_frames_removed
  File "/opt/airflow/dags/desafio-airflow/desafio-indicium.py", line 4, in <module>
    from func_le_dados import leitura
ModuleNotFoundError: No module named 'func_le_dados'
[2022-10-09T22:21:50.387+0000] {processor.py:770} WARNING - No viable dags retrieved from /opt/airflow/dags/desafio-airflow/desafio-indicium.py
[2022-10-09T22:21:50.453+0000] {processor.py:178} INFO - Processing /opt/airflow/dags/desafio-airflow/desafio-indicium.py took 0.499 seconds
[2022-10-09T22:22:20.678+0000] {processor.py:156} INFO - Started process (PID=16471) to work on /opt/airflow/dags/desafio-airflow/desafio-indicium.py
[2022-10-09T22:22:20.679+0000] {processor.py:758} INFO - Processing file /opt/airflow/dags/desafio-airflow/desafio-indicium.py for tasks to queue
[2022-10-09T22:22:20.679+0000] {logging_mixin.py:117} INFO - [2022-10-09T22:22:20.679+0000] {dagbag.py:525} INFO - Filling up the DagBag from /opt/airflow/dags/desafio-airflow/desafio-indicium.py
[2022-10-09T22:22:21.091+0000] {logging_mixin.py:117} INFO - [2022-10-09T22:22:21.089+0000] {dagbag.py:330} ERROR - Failed to import: /opt/airflow/dags/desafio-airflow/desafio-indicium.py
Traceback (most recent call last):
  File "/home/airflow/.local/lib/python3.7/site-packages/airflow/models/dagbag.py", line 326, in parse
    loader.exec_module(new_module)
  File "<frozen importlib._bootstrap_external>", line 728, in exec_module
  File "<frozen importlib._bootstrap>", line 219, in _call_with_frames_removed
  File "/opt/airflow/dags/desafio-airflow/desafio-indicium.py", line 4, in <module>
    from func_le_dados import leitura
ModuleNotFoundError: No module named 'func_le_dados'
[2022-10-09T22:22:21.092+0000] {processor.py:770} WARNING - No viable dags retrieved from /opt/airflow/dags/desafio-airflow/desafio-indicium.py
[2022-10-09T22:22:21.120+0000] {processor.py:178} INFO - Processing /opt/airflow/dags/desafio-airflow/desafio-indicium.py took 0.448 seconds
[2022-10-09T22:22:44.010+0000] {processor.py:156} INFO - Started process (PID=16516) to work on /opt/airflow/dags/desafio-airflow/desafio-indicium.py
[2022-10-09T22:22:44.011+0000] {processor.py:758} INFO - Processing file /opt/airflow/dags/desafio-airflow/desafio-indicium.py for tasks to queue
[2022-10-09T22:22:44.011+0000] {logging_mixin.py:117} INFO - [2022-10-09T22:22:44.011+0000] {dagbag.py:525} INFO - Filling up the DagBag from /opt/airflow/dags/desafio-airflow/desafio-indicium.py
[2022-10-09T22:22:44.015+0000] {logging_mixin.py:117} INFO - [2022-10-09T22:22:44.013+0000] {dagbag.py:330} ERROR - Failed to import: /opt/airflow/dags/desafio-airflow/desafio-indicium.py
Traceback (most recent call last):
  File "/home/airflow/.local/lib/python3.7/site-packages/airflow/models/dagbag.py", line 326, in parse
    loader.exec_module(new_module)
  File "<frozen importlib._bootstrap_external>", line 724, in exec_module
  File "<frozen importlib._bootstrap_external>", line 860, in get_code
  File "<frozen importlib._bootstrap_external>", line 791, in source_to_code
  File "<frozen importlib._bootstrap>", line 219, in _call_with_frames_removed
  File "/opt/airflow/dags/desafio-airflow/desafio-indicium.py", line 4
    from func-le-dados import leitura
             ^
SyntaxError: invalid syntax
[2022-10-09T22:22:44.015+0000] {processor.py:770} WARNING - No viable dags retrieved from /opt/airflow/dags/desafio-airflow/desafio-indicium.py
[2022-10-09T22:22:44.048+0000] {processor.py:178} INFO - Processing /opt/airflow/dags/desafio-airflow/desafio-indicium.py took 0.042 seconds
[2022-10-09T22:23:14.870+0000] {processor.py:156} INFO - Started process (PID=16580) to work on /opt/airflow/dags/desafio-airflow/desafio-indicium.py
[2022-10-09T22:23:14.877+0000] {processor.py:758} INFO - Processing file /opt/airflow/dags/desafio-airflow/desafio-indicium.py for tasks to queue
[2022-10-09T22:23:14.879+0000] {logging_mixin.py:117} INFO - [2022-10-09T22:23:14.879+0000] {dagbag.py:525} INFO - Filling up the DagBag from /opt/airflow/dags/desafio-airflow/desafio-indicium.py
[2022-10-09T22:23:14.883+0000] {logging_mixin.py:117} INFO - [2022-10-09T22:23:14.881+0000] {dagbag.py:330} ERROR - Failed to import: /opt/airflow/dags/desafio-airflow/desafio-indicium.py
Traceback (most recent call last):
  File "/home/airflow/.local/lib/python3.7/site-packages/airflow/models/dagbag.py", line 326, in parse
    loader.exec_module(new_module)
  File "<frozen importlib._bootstrap_external>", line 724, in exec_module
  File "<frozen importlib._bootstrap_external>", line 860, in get_code
  File "<frozen importlib._bootstrap_external>", line 791, in source_to_code
  File "<frozen importlib._bootstrap>", line 219, in _call_with_frames_removed
  File "/opt/airflow/dags/desafio-airflow/desafio-indicium.py", line 4
    from func-le-dados import leitura
             ^
SyntaxError: invalid syntax
[2022-10-09T22:23:14.883+0000] {processor.py:770} WARNING - No viable dags retrieved from /opt/airflow/dags/desafio-airflow/desafio-indicium.py
[2022-10-09T22:23:14.915+0000] {processor.py:178} INFO - Processing /opt/airflow/dags/desafio-airflow/desafio-indicium.py took 0.050 seconds
[2022-10-09T22:23:45.785+0000] {processor.py:156} INFO - Started process (PID=16635) to work on /opt/airflow/dags/desafio-airflow/desafio-indicium.py
[2022-10-09T22:23:45.792+0000] {processor.py:758} INFO - Processing file /opt/airflow/dags/desafio-airflow/desafio-indicium.py for tasks to queue
[2022-10-09T22:23:45.792+0000] {logging_mixin.py:117} INFO - [2022-10-09T22:23:45.792+0000] {dagbag.py:525} INFO - Filling up the DagBag from /opt/airflow/dags/desafio-airflow/desafio-indicium.py
[2022-10-09T22:23:45.795+0000] {logging_mixin.py:117} INFO - [2022-10-09T22:23:45.794+0000] {dagbag.py:330} ERROR - Failed to import: /opt/airflow/dags/desafio-airflow/desafio-indicium.py
Traceback (most recent call last):
  File "/home/airflow/.local/lib/python3.7/site-packages/airflow/models/dagbag.py", line 326, in parse
    loader.exec_module(new_module)
  File "<frozen importlib._bootstrap_external>", line 724, in exec_module
  File "<frozen importlib._bootstrap_external>", line 860, in get_code
  File "<frozen importlib._bootstrap_external>", line 791, in source_to_code
  File "<frozen importlib._bootstrap>", line 219, in _call_with_frames_removed
  File "/opt/airflow/dags/desafio-airflow/desafio-indicium.py", line 4
    from func-le-dados import leitura
             ^
SyntaxError: invalid syntax
[2022-10-09T22:23:45.796+0000] {processor.py:770} WARNING - No viable dags retrieved from /opt/airflow/dags/desafio-airflow/desafio-indicium.py
[2022-10-09T22:23:45.822+0000] {processor.py:178} INFO - Processing /opt/airflow/dags/desafio-airflow/desafio-indicium.py took 0.041 seconds
[2022-10-09T22:24:16.030+0000] {processor.py:156} INFO - Started process (PID=16699) to work on /opt/airflow/dags/desafio-airflow/desafio-indicium.py
[2022-10-09T22:24:16.032+0000] {processor.py:758} INFO - Processing file /opt/airflow/dags/desafio-airflow/desafio-indicium.py for tasks to queue
[2022-10-09T22:24:16.033+0000] {logging_mixin.py:117} INFO - [2022-10-09T22:24:16.033+0000] {dagbag.py:525} INFO - Filling up the DagBag from /opt/airflow/dags/desafio-airflow/desafio-indicium.py
[2022-10-09T22:24:16.037+0000] {logging_mixin.py:117} INFO - [2022-10-09T22:24:16.035+0000] {dagbag.py:330} ERROR - Failed to import: /opt/airflow/dags/desafio-airflow/desafio-indicium.py
Traceback (most recent call last):
  File "/home/airflow/.local/lib/python3.7/site-packages/airflow/models/dagbag.py", line 326, in parse
    loader.exec_module(new_module)
  File "<frozen importlib._bootstrap_external>", line 724, in exec_module
  File "<frozen importlib._bootstrap_external>", line 860, in get_code
  File "<frozen importlib._bootstrap_external>", line 791, in source_to_code
  File "<frozen importlib._bootstrap>", line 219, in _call_with_frames_removed
  File "/opt/airflow/dags/desafio-airflow/desafio-indicium.py", line 4
    from func-le-dados import leitura
             ^
SyntaxError: invalid syntax
[2022-10-09T22:24:16.037+0000] {processor.py:770} WARNING - No viable dags retrieved from /opt/airflow/dags/desafio-airflow/desafio-indicium.py
[2022-10-09T22:24:16.076+0000] {processor.py:178} INFO - Processing /opt/airflow/dags/desafio-airflow/desafio-indicium.py took 0.052 seconds
[2022-10-09T22:24:46.685+0000] {processor.py:156} INFO - Started process (PID=16754) to work on /opt/airflow/dags/desafio-airflow/desafio-indicium.py
[2022-10-09T22:24:46.687+0000] {processor.py:758} INFO - Processing file /opt/airflow/dags/desafio-airflow/desafio-indicium.py for tasks to queue
[2022-10-09T22:24:46.688+0000] {logging_mixin.py:117} INFO - [2022-10-09T22:24:46.687+0000] {dagbag.py:525} INFO - Filling up the DagBag from /opt/airflow/dags/desafio-airflow/desafio-indicium.py
[2022-10-09T22:24:46.691+0000] {logging_mixin.py:117} INFO - [2022-10-09T22:24:46.689+0000] {dagbag.py:330} ERROR - Failed to import: /opt/airflow/dags/desafio-airflow/desafio-indicium.py
Traceback (most recent call last):
  File "/home/airflow/.local/lib/python3.7/site-packages/airflow/models/dagbag.py", line 326, in parse
    loader.exec_module(new_module)
  File "<frozen importlib._bootstrap_external>", line 724, in exec_module
  File "<frozen importlib._bootstrap_external>", line 860, in get_code
  File "<frozen importlib._bootstrap_external>", line 791, in source_to_code
  File "<frozen importlib._bootstrap>", line 219, in _call_with_frames_removed
  File "/opt/airflow/dags/desafio-airflow/desafio-indicium.py", line 4
    from func-le-dados import leitura
             ^
SyntaxError: invalid syntax
[2022-10-09T22:24:46.691+0000] {processor.py:770} WARNING - No viable dags retrieved from /opt/airflow/dags/desafio-airflow/desafio-indicium.py
[2022-10-09T22:24:46.727+0000] {processor.py:178} INFO - Processing /opt/airflow/dags/desafio-airflow/desafio-indicium.py took 0.048 seconds
[2022-10-09T22:25:17.486+0000] {processor.py:156} INFO - Started process (PID=16818) to work on /opt/airflow/dags/desafio-airflow/desafio-indicium.py
[2022-10-09T22:25:17.494+0000] {processor.py:758} INFO - Processing file /opt/airflow/dags/desafio-airflow/desafio-indicium.py for tasks to queue
[2022-10-09T22:25:17.496+0000] {logging_mixin.py:117} INFO - [2022-10-09T22:25:17.495+0000] {dagbag.py:525} INFO - Filling up the DagBag from /opt/airflow/dags/desafio-airflow/desafio-indicium.py
[2022-10-09T22:25:17.500+0000] {logging_mixin.py:117} INFO - [2022-10-09T22:25:17.498+0000] {dagbag.py:330} ERROR - Failed to import: /opt/airflow/dags/desafio-airflow/desafio-indicium.py
Traceback (most recent call last):
  File "/home/airflow/.local/lib/python3.7/site-packages/airflow/models/dagbag.py", line 326, in parse
    loader.exec_module(new_module)
  File "<frozen importlib._bootstrap_external>", line 724, in exec_module
  File "<frozen importlib._bootstrap_external>", line 860, in get_code
  File "<frozen importlib._bootstrap_external>", line 791, in source_to_code
  File "<frozen importlib._bootstrap>", line 219, in _call_with_frames_removed
  File "/opt/airflow/dags/desafio-airflow/desafio-indicium.py", line 4
    from func-le-dados import leitura
             ^
SyntaxError: invalid syntax
[2022-10-09T22:25:17.501+0000] {processor.py:770} WARNING - No viable dags retrieved from /opt/airflow/dags/desafio-airflow/desafio-indicium.py
[2022-10-09T22:25:17.541+0000] {processor.py:178} INFO - Processing /opt/airflow/dags/desafio-airflow/desafio-indicium.py took 0.060 seconds
[2022-10-09T22:55:14.307+0000] {processor.py:156} INFO - Started process (PID=16822) to work on /opt/airflow/dags/desafio-airflow/desafio-indicium.py
[2022-10-09T22:55:14.308+0000] {processor.py:758} INFO - Processing file /opt/airflow/dags/desafio-airflow/desafio-indicium.py for tasks to queue
[2022-10-09T22:55:14.309+0000] {logging_mixin.py:117} INFO - [2022-10-09T22:55:14.309+0000] {dagbag.py:525} INFO - Filling up the DagBag from /opt/airflow/dags/desafio-airflow/desafio-indicium.py
[2022-10-09T22:55:14.311+0000] {logging_mixin.py:117} INFO - [2022-10-09T22:55:14.310+0000] {dagbag.py:330} ERROR - Failed to import: /opt/airflow/dags/desafio-airflow/desafio-indicium.py
Traceback (most recent call last):
  File "/home/airflow/.local/lib/python3.7/site-packages/airflow/models/dagbag.py", line 326, in parse
    loader.exec_module(new_module)
  File "<frozen importlib._bootstrap_external>", line 724, in exec_module
  File "<frozen importlib._bootstrap_external>", line 860, in get_code
  File "<frozen importlib._bootstrap_external>", line 791, in source_to_code
  File "<frozen importlib._bootstrap>", line 219, in _call_with_frames_removed
  File "/opt/airflow/dags/desafio-airflow/desafio-indicium.py", line 4
    from func-le-dados import leitura
             ^
SyntaxError: invalid syntax
[2022-10-09T22:55:14.312+0000] {processor.py:770} WARNING - No viable dags retrieved from /opt/airflow/dags/desafio-airflow/desafio-indicium.py
[2022-10-09T22:55:14.339+0000] {processor.py:178} INFO - Processing /opt/airflow/dags/desafio-airflow/desafio-indicium.py took 0.038 seconds
[2022-10-09T22:55:44.868+0000] {processor.py:156} INFO - Started process (PID=16886) to work on /opt/airflow/dags/desafio-airflow/desafio-indicium.py
[2022-10-09T22:55:44.875+0000] {processor.py:758} INFO - Processing file /opt/airflow/dags/desafio-airflow/desafio-indicium.py for tasks to queue
[2022-10-09T22:55:44.877+0000] {logging_mixin.py:117} INFO - [2022-10-09T22:55:44.876+0000] {dagbag.py:525} INFO - Filling up the DagBag from /opt/airflow/dags/desafio-airflow/desafio-indicium.py
[2022-10-09T22:55:44.880+0000] {logging_mixin.py:117} INFO - [2022-10-09T22:55:44.879+0000] {dagbag.py:330} ERROR - Failed to import: /opt/airflow/dags/desafio-airflow/desafio-indicium.py
Traceback (most recent call last):
  File "/home/airflow/.local/lib/python3.7/site-packages/airflow/models/dagbag.py", line 326, in parse
    loader.exec_module(new_module)
  File "<frozen importlib._bootstrap_external>", line 724, in exec_module
  File "<frozen importlib._bootstrap_external>", line 860, in get_code
  File "<frozen importlib._bootstrap_external>", line 791, in source_to_code
  File "<frozen importlib._bootstrap>", line 219, in _call_with_frames_removed
  File "/opt/airflow/dags/desafio-airflow/desafio-indicium.py", line 4
    from func-le-dados import leitura
             ^
SyntaxError: invalid syntax
[2022-10-09T22:55:44.881+0000] {processor.py:770} WARNING - No viable dags retrieved from /opt/airflow/dags/desafio-airflow/desafio-indicium.py
[2022-10-09T22:55:44.908+0000] {processor.py:178} INFO - Processing /opt/airflow/dags/desafio-airflow/desafio-indicium.py took 0.047 seconds
[2022-10-09T22:56:04.505+0000] {processor.py:156} INFO - Started process (PID=16931) to work on /opt/airflow/dags/desafio-airflow/desafio-indicium.py
[2022-10-09T22:56:04.512+0000] {processor.py:758} INFO - Processing file /opt/airflow/dags/desafio-airflow/desafio-indicium.py for tasks to queue
[2022-10-09T22:56:04.513+0000] {logging_mixin.py:117} INFO - [2022-10-09T22:56:04.513+0000] {dagbag.py:525} INFO - Filling up the DagBag from /opt/airflow/dags/desafio-airflow/desafio-indicium.py
[2022-10-09T22:56:04.515+0000] {logging_mixin.py:117} INFO - [2022-10-09T22:56:04.514+0000] {dagbag.py:330} ERROR - Failed to import: /opt/airflow/dags/desafio-airflow/desafio-indicium.py
Traceback (most recent call last):
  File "/home/airflow/.local/lib/python3.7/site-packages/airflow/models/dagbag.py", line 326, in parse
    loader.exec_module(new_module)
  File "<frozen importlib._bootstrap_external>", line 724, in exec_module
  File "<frozen importlib._bootstrap_external>", line 860, in get_code
  File "<frozen importlib._bootstrap_external>", line 791, in source_to_code
  File "<frozen importlib._bootstrap>", line 219, in _call_with_frames_removed
  File "/opt/airflow/dags/desafio-airflow/desafio-indicium.py", line 4
    from desafio-airflow.func-le-dados import leitura
                ^
SyntaxError: invalid syntax
[2022-10-09T22:56:04.516+0000] {processor.py:770} WARNING - No viable dags retrieved from /opt/airflow/dags/desafio-airflow/desafio-indicium.py
[2022-10-09T22:56:04.544+0000] {processor.py:178} INFO - Processing /opt/airflow/dags/desafio-airflow/desafio-indicium.py took 0.044 seconds
[2022-10-09T22:56:35.418+0000] {processor.py:156} INFO - Started process (PID=16995) to work on /opt/airflow/dags/desafio-airflow/desafio-indicium.py
[2022-10-09T22:56:35.419+0000] {processor.py:758} INFO - Processing file /opt/airflow/dags/desafio-airflow/desafio-indicium.py for tasks to queue
[2022-10-09T22:56:35.420+0000] {logging_mixin.py:117} INFO - [2022-10-09T22:56:35.419+0000] {dagbag.py:525} INFO - Filling up the DagBag from /opt/airflow/dags/desafio-airflow/desafio-indicium.py
[2022-10-09T22:56:35.426+0000] {logging_mixin.py:117} INFO - [2022-10-09T22:56:35.424+0000] {dagbag.py:330} ERROR - Failed to import: /opt/airflow/dags/desafio-airflow/desafio-indicium.py
Traceback (most recent call last):
  File "/home/airflow/.local/lib/python3.7/site-packages/airflow/models/dagbag.py", line 326, in parse
    loader.exec_module(new_module)
  File "<frozen importlib._bootstrap_external>", line 724, in exec_module
  File "<frozen importlib._bootstrap_external>", line 860, in get_code
  File "<frozen importlib._bootstrap_external>", line 791, in source_to_code
  File "<frozen importlib._bootstrap>", line 219, in _call_with_frames_removed
  File "/opt/airflow/dags/desafio-airflow/desafio-indicium.py", line 4
    from desafio-airflow.func-le-dados import leitura
                ^
SyntaxError: invalid syntax
[2022-10-09T22:56:35.427+0000] {processor.py:770} WARNING - No viable dags retrieved from /opt/airflow/dags/desafio-airflow/desafio-indicium.py
[2022-10-09T22:56:35.461+0000] {processor.py:178} INFO - Processing /opt/airflow/dags/desafio-airflow/desafio-indicium.py took 0.049 seconds
[2022-10-09T22:57:05.901+0000] {processor.py:156} INFO - Started process (PID=17059) to work on /opt/airflow/dags/desafio-airflow/desafio-indicium.py
[2022-10-09T22:57:05.908+0000] {processor.py:758} INFO - Processing file /opt/airflow/dags/desafio-airflow/desafio-indicium.py for tasks to queue
[2022-10-09T22:57:05.909+0000] {logging_mixin.py:117} INFO - [2022-10-09T22:57:05.909+0000] {dagbag.py:525} INFO - Filling up the DagBag from /opt/airflow/dags/desafio-airflow/desafio-indicium.py
[2022-10-09T22:57:05.913+0000] {logging_mixin.py:117} INFO - [2022-10-09T22:57:05.911+0000] {dagbag.py:330} ERROR - Failed to import: /opt/airflow/dags/desafio-airflow/desafio-indicium.py
Traceback (most recent call last):
  File "/home/airflow/.local/lib/python3.7/site-packages/airflow/models/dagbag.py", line 326, in parse
    loader.exec_module(new_module)
  File "<frozen importlib._bootstrap_external>", line 724, in exec_module
  File "<frozen importlib._bootstrap_external>", line 860, in get_code
  File "<frozen importlib._bootstrap_external>", line 791, in source_to_code
  File "<frozen importlib._bootstrap>", line 219, in _call_with_frames_removed
  File "/opt/airflow/dags/desafio-airflow/desafio-indicium.py", line 4
    from desafio-airflow.func-le-dados import leitura
                ^
SyntaxError: invalid syntax
[2022-10-09T22:57:05.913+0000] {processor.py:770} WARNING - No viable dags retrieved from /opt/airflow/dags/desafio-airflow/desafio-indicium.py
[2022-10-09T22:57:05.943+0000] {processor.py:178} INFO - Processing /opt/airflow/dags/desafio-airflow/desafio-indicium.py took 0.047 seconds
[2022-10-09T22:57:36.026+0000] {processor.py:156} INFO - Started process (PID=17116) to work on /opt/airflow/dags/desafio-airflow/desafio-indicium.py
[2022-10-09T22:57:36.027+0000] {processor.py:758} INFO - Processing file /opt/airflow/dags/desafio-airflow/desafio-indicium.py for tasks to queue
[2022-10-09T22:57:36.028+0000] {logging_mixin.py:117} INFO - [2022-10-09T22:57:36.027+0000] {dagbag.py:525} INFO - Filling up the DagBag from /opt/airflow/dags/desafio-airflow/desafio-indicium.py
[2022-10-09T22:57:36.030+0000] {logging_mixin.py:117} INFO - [2022-10-09T22:57:36.029+0000] {dagbag.py:330} ERROR - Failed to import: /opt/airflow/dags/desafio-airflow/desafio-indicium.py
Traceback (most recent call last):
  File "/home/airflow/.local/lib/python3.7/site-packages/airflow/models/dagbag.py", line 326, in parse
    loader.exec_module(new_module)
  File "<frozen importlib._bootstrap_external>", line 724, in exec_module
  File "<frozen importlib._bootstrap_external>", line 860, in get_code
  File "<frozen importlib._bootstrap_external>", line 791, in source_to_code
  File "<frozen importlib._bootstrap>", line 219, in _call_with_frames_removed
  File "/opt/airflow/dags/desafio-airflow/desafio-indicium.py", line 4
    from desafio-airflow.func-le-dados import leitura
                ^
SyntaxError: invalid syntax
[2022-10-09T22:57:36.030+0000] {processor.py:770} WARNING - No viable dags retrieved from /opt/airflow/dags/desafio-airflow/desafio-indicium.py
[2022-10-09T22:57:36.058+0000] {processor.py:178} INFO - Processing /opt/airflow/dags/desafio-airflow/desafio-indicium.py took 0.038 seconds
[2022-10-09T22:57:40.066+0000] {processor.py:156} INFO - Started process (PID=17117) to work on /opt/airflow/dags/desafio-airflow/desafio-indicium.py
[2022-10-09T22:57:40.067+0000] {processor.py:758} INFO - Processing file /opt/airflow/dags/desafio-airflow/desafio-indicium.py for tasks to queue
[2022-10-09T22:57:40.068+0000] {logging_mixin.py:117} INFO - [2022-10-09T22:57:40.068+0000] {dagbag.py:525} INFO - Filling up the DagBag from /opt/airflow/dags/desafio-airflow/desafio-indicium.py
[2022-10-09T22:57:40.072+0000] {logging_mixin.py:117} INFO - [2022-10-09T22:57:40.070+0000] {dagbag.py:330} ERROR - Failed to import: /opt/airflow/dags/desafio-airflow/desafio-indicium.py
Traceback (most recent call last):
  File "/home/airflow/.local/lib/python3.7/site-packages/airflow/models/dagbag.py", line 326, in parse
    loader.exec_module(new_module)
  File "<frozen importlib._bootstrap_external>", line 724, in exec_module
  File "<frozen importlib._bootstrap_external>", line 860, in get_code
  File "<frozen importlib._bootstrap_external>", line 791, in source_to_code
  File "<frozen importlib._bootstrap>", line 219, in _call_with_frames_removed
  File "/opt/airflow/dags/desafio-airflow/desafio-indicium.py", line 4
    from dags.desafio-airflow.func-le-dados import leitura
                     ^
SyntaxError: invalid syntax
[2022-10-09T22:57:40.072+0000] {processor.py:770} WARNING - No viable dags retrieved from /opt/airflow/dags/desafio-airflow/desafio-indicium.py
[2022-10-09T22:57:40.103+0000] {processor.py:178} INFO - Processing /opt/airflow/dags/desafio-airflow/desafio-indicium.py took 0.042 seconds
[2022-10-09T22:58:10.424+0000] {processor.py:156} INFO - Started process (PID=17181) to work on /opt/airflow/dags/desafio-airflow/desafio-indicium.py
[2022-10-09T22:58:10.432+0000] {processor.py:758} INFO - Processing file /opt/airflow/dags/desafio-airflow/desafio-indicium.py for tasks to queue
[2022-10-09T22:58:10.433+0000] {logging_mixin.py:117} INFO - [2022-10-09T22:58:10.433+0000] {dagbag.py:525} INFO - Filling up the DagBag from /opt/airflow/dags/desafio-airflow/desafio-indicium.py
[2022-10-09T22:58:10.437+0000] {logging_mixin.py:117} INFO - [2022-10-09T22:58:10.436+0000] {dagbag.py:330} ERROR - Failed to import: /opt/airflow/dags/desafio-airflow/desafio-indicium.py
Traceback (most recent call last):
  File "/home/airflow/.local/lib/python3.7/site-packages/airflow/models/dagbag.py", line 326, in parse
    loader.exec_module(new_module)
  File "<frozen importlib._bootstrap_external>", line 724, in exec_module
  File "<frozen importlib._bootstrap_external>", line 860, in get_code
  File "<frozen importlib._bootstrap_external>", line 791, in source_to_code
  File "<frozen importlib._bootstrap>", line 219, in _call_with_frames_removed
  File "/opt/airflow/dags/desafio-airflow/desafio-indicium.py", line 4
    from dags.desafio-airflow.func-le-dados import leitura
                     ^
SyntaxError: invalid syntax
[2022-10-09T22:58:10.438+0000] {processor.py:770} WARNING - No viable dags retrieved from /opt/airflow/dags/desafio-airflow/desafio-indicium.py
[2022-10-09T22:58:10.470+0000] {processor.py:178} INFO - Processing /opt/airflow/dags/desafio-airflow/desafio-indicium.py took 0.050 seconds
